Workbook

Sheet paste report
A1: Report: | D1: Weekly Schedule: [ System ]
A2: Sorted By: | D2: Employee Id Ascending
A3: Filtered By: | D3: Employee Filter: All Employees; Date Range: 01/09/2025-07/09/2025; Extra Settings: Show Time Off, Highlight Last Opened Schedule; Cost Center(Store) = chatswood concourse; Employee Status != Terminated
A4: Date & Time: | D4: 25/08/2025 03:59p
A5: Generated By: | D5: Hui Fern Hwa, Level 8
A6: Company: | D6: Muji Retail Australia Pty Ltd (6147268)
A8: Employee Id | B8: First Name | C8: Last Name | D8: Employee Status | E8: Schedule Mon Nov 10 | F8: Schedule Tue Nov 11 | G8: Schedule Wed Nov 12 | H8: Schedule Thu Nov 13 | I8: Schedule Fri Nov 14 | J8: Schedule Sat Nov 15 | K8: Schedule Sun Nov 16 | L8: Cost Center(Store)
A9: 01509 | B9: Amy | C9: Somana | D9: Active | F9: 08:30a - 04:30p | G9: 08:30a - 04:30p | H9: 08:30a - 05:00p | I9: 08:30a - 04:30p | J9: 12:00p - 08:00p | L9: Chatswood Concourse
A10: 1175 | B10: Anna | C10: Naritsuka-Hayler | D10: Active | F10: 08:30a - 04:30p | G10: 08:30a - 04:30p | K10: 12:00p - 08:00p | L10: Chatswood Concourse
A11: 1041 | B11: Archana | C11: Prashanth | D11: Active | L11: Chatswood Concourse
A12: 1245 | B12: Charlotte | C12: Robertson | D12: Active | L12: Chatswood Concourse
A13: 1136 | B13: Cherry | C13: Ward | D13: Active | G13: 11:00a - 07:00p | I13: 11:00a - 07:00p | K13: 12:00p - 08:00p | L13: Chatswood Concourse
A14: 1247 | B14: Chihiro | C14: Burgoyne | D14: Active | E14: 08:30a - 03:00p | F14: 08:30a - 03:00p | G14: 08:30a - 03:00p | H14: 08:30a - 03:00p | I14: 08:30a - 03:00p | L14: Chatswood Concourse
A15: 01514 | B15: Chloe | C15: Huang | D15: Active | E15: 10:30a - 07:00p | F15: 11:00a - 07:00p | G15: 11:00a - 07:00p | H15: 02:00p - 10:00p | K15: 12:00p - 08:00p | L15: Chatswood Concourse
A16: 660 | B16: Daniel | C16: Park | D16: Active | L16: Chatswood Concourse
A17: 1275 | B17: Da-yeon | C17: Oh | D17: Active | L17: Chatswood Concourse
A18: 1258 | B18: Dennis | C18: Kim | D18: Active | J18: 03:00p - 08:00p | L18: Chatswood Concourse
A19: 1131 | B19: Doris | C19: Hou | D19: Active | L19: Chatswood Concourse
A20: 01601 | B20: Dorothy | C20: Choi | D20: Active | J20: 11:00a - 07:00p | L20: Chatswood Concourse
A21: 01506 | B21: Duke | C21: Trac | D21: Active | H21: 02:00p - 10:00p | J21: 12:00p - 08:00p | K21: 12:00p - 08:00p | L21: Chatswood Concourse
A22: 01526 | B22: Emma | C22: Blackburn | D22: Active | L22: Chatswood Concourse
A23: 1025 | B23: Eunice | C23: Deng | D23: Active | L23: Chatswood Concourse
A24: 670 | B24: Fern | C24: Hwa | D24: Active | E24: 10:30a - 07:00p | F24: 11:00a - 07:00p | G24: 08:30a - 04:30p | H24: 02:00p - 10:00p | K24: 12:00p - 08:00p | L24: Chatswood Concourse
A25: 01504 | B25: Hannah | C25: Abad | D25: Active | E25: 02:00p - 07:00p | H25: 04:00p - 09:00p | I25: 02:00p - 07:00p | L25: Chatswood Concourse
A26: 01524 | B26: Isabelle | C26: Lee | D26: Active | F26: 11:00a - 07:00p | K26: 09:00a - 05:00p | L26: Chatswood Concourse
A27: 1216 | B27: Janelle | C27: Viernes | D27: Active | K27: 12:00p - 08:00p | L27: Chatswood Concourse
A28: 1228 | B28: Jared | C28: Hui | D28: Active | G28: 11:00a - 07:00p | H28: 02:00p - 10:00p | K28: 12:00p - 08:00p | L28: Chatswood Concourse
A29: 1196 | B29: Jessica | C29: Rao | D29: Active | F29: 11:00a - 07:00p | G29: 08:30a - 04:30p | H29: 08:30a - 04:30p | I29: 11:00a - 07:00p | J29: 12:00p - 08:00p | L29: Chatswood Concourse
A30: 01520 | B30: Jessie | C30: Zhang | D30: Active | L30: Chatswood Concourse
A31: 01505 | B31: Jewel | C31: Yabut | D31: Active | K31: 09:00a - 02:00p | L31: Chatswood Concourse
A32: 1289 | B32: Jordan | C32: Shue | D32: Active | E32: 10:30a - 07:00p | F32: 11:00a - 07:00p | G32: 11:00a - 07:00p | H32: 02:00p - 10:00p | K32: 09:00a - 05:00p | L32: Chatswood Concourse
A33: 1094 | B33: Joslyn | C33: Lam | D33: Active | G33: 08:30a - 04:30p | H33: 08:30a - 04:30p | K33: 09:00a - 05:00p | L33: Chatswood Concourse
A34: 1014 | B34: Julie K. | C34: Ko | D34: Active | E34: 08:30a - 04:30p | J34: 09:00a - 05:00p | L34: Chatswood Concourse
A35: 01518 | B35: Julie L. | C35: Luong | D35: Active | E35: 11:00a - 07:00p | I35: 11:00a - 07:00p | J35: 09:00a - 05:00p | L35: Chatswood Concourse
A36: 01527 | B36: Justine | C36: Sy | D36: Active | I36: 11:00a - 07:00p | J36: 09:00a - 02:00p | K36: 09:00a - 05:00p | L36: Chatswood Concourse
A37: 01519 | B37: Kathy | C37: Htun | D37: Active | H37: 11:00a - 07:00p | I37: 11:00a - 07:00p | K37: 12:00p - 08:00p | L37: Chatswood Concourse
A38: 1143 | B38: Kaye | C38: Bongolan | D38: Active | I38: 08:30a - 04:30p | J38: 12:00p - 08:00p | K38: 11:00a - 07:00p | L38: Chatswood Concourse
A39: 01523 | B39: Lachlan | C39: Ng | D39: Active | L39: Chatswood Concourse
A40: 614 | B40: Lauren | C40: Huynh | D40: Active | L40: Chatswood Concourse
A41: 01517 | B41: Lona | C41: Simkhada | D41: Active | E41: 08:30a - 04:30p | F41: 08:30a - 04:30p | G41: 08:30a - 04:30p | K41: 09:00a - 05:00p | L41: Chatswood Concourse
...

Sheet Info
B2: For shifts with a 40 min and 10 min break the 10 min breaks are 1:30 or 1:45 before the end of a 7.5 to 8.5 hr shift or 1:45 to 2:00 before the end of a +9hr shift
B3: For shifts with only a 10 min break it is either a the midpoint of the shift or 10 min before the midpoint
D5: Number of hours worked | E5: Rest breaks | F5: Meal breaks | H5: Keep
D6: < 4 hours | E6: 0 | F6: 0 | H6: 0.010416667
D7: 4 to 5 hours | E7: 1 | F7: 0 | G7: 1 x 10 | H7: 0.03125
D8: >5 to <7 hours | E8: 1 | F8: 1 | G8: 1 x 40 | H8: 0.22916667
D9: 7 to < 10 hours | E9: 2 | F9: 1 | G9: 1 x 40 & 1 x 10 | H9: 0.03125
D10: 10 or more hours | E10: 2 | F10: 2 | G10: 2 x 40 | H10: 0.16666667
C13: M's | D13: Mens (incl. M's inner)
C14: L's | D14: Ladies (incl. W's inner)
C15: K's | D15: Kids
C16: M/K | D16: Mens + Kids
C17: Acc. | D17: Accessories
C18: Fab. | D18: Fabric
C19: HW | D19: Homewear
C20: Stat. | D20: Stationery
C21: H&B | D21: Health & Beauty
C22: HH | D22: Household
C23: F | D23: Food
C24: 40 | D24: 40min break
C25: 15 | D25: 15min break
C26: 10 | D26: 10min break
C27: R | D27: Register
C28: FR | D28: Fitting room
C29: LD | D29: Leader
C30: GR | D30: Greeter
C31: H | D31: Huddle
C32: MT | D32: Meeting (for SM/ASM)
C33: CL | D33: Cleaning
C34: Mirr. | D34: Cleaning of Mirrors
C35: Dust | D35: Dusting of shelves/top
C36: Vac. | D36: Vaccum
C37: CL S | D37: Cleaning Staffroom
C38: Bin | D38: Bin run
... C42: Tidy | D42: Tidy (after closing)

Sheet Team
E2: For Department, use one of the acronym used in the "info" sheet | F2: For contract type, only use one of the 3 options below: FT PT Cas
B3: Employee Id | C3: First Name | D3: Last Name | E3: Department | F3: Contract type
B4: 01509 | C4: Amy | D4: Somana | E4: L's | F4: FT
B5: 1175 | C5: Anna | D5: Naritsuka-Hayler | E5: H&B | F5: PT
B6: 1041 | C6: Archana | D6: Prashanth | E6: L's | F6: CAS
B7: 1245 | C7: Charlotte | D7: Robertson | E7: HH | F7: CAS
B8: 1136 | C8: Cherry | D8: Ward | E8: M's | F8: PT
B9: 1247 | C9: Chihiro | D9: Burgoyne | E9: HH | F9: PT
B10: 01514 | C10: Chloe | D10: Huang | E10: SPV | F10: FT
B11: 660 | C11: Daniel | D11: Park | E11: HH | F11: CAS
B12: 1275 | C12: Da-yeon | D12: Oh | E12: HH | F12: CAS
B13: 1258 | C13: Dennis | D13: Kim | E13: Stat. | F13: CAS
B14: 1131 | C14: Doris | D14: Hou | E14: L's | F14: CAS
... B56: 1160 | C56: Yura | D56: Sin | E56: SPV | F56: FT

Sheet Weekly
G2: =RIGHT('paste report'!E8,11) -> Mon Nov 10 | J2: =RIGHT('paste report'!F8,11) -> Tue Nov 11 | M2: =RIGHT('paste report'!G8,11) -> Wed Nov 12 | P2: =RIGHT('paste report'!H8,11) -> Thu Nov 13 | S2: =RIGHT('paste report'!I8,11) -> Fri Nov 14 | V2: =RIGHT('paste report'!J8,11) -> Sat Nov 15 | Y2: =RIGHT('paste report'!K8,11) -> Sun Nov 16
C3: Weekly MH | D3: =I7+L7+O7+R7+U7+X7+AA7 -> 432 | M3: Delivery | S3: Delivery
G4: Full time | I4: =SUMIF($E$10:$E$97,"FT",I10:I97) -> 34 | J4: Full time | L4: =SUMIF($E$10:$E$97,"FT",L10:L97) -> 48.5 | M4: Full time | O4: =SUMIF($E$10:$E$97,"FT",O10:O97) -> 48 | P4: Full time | R4: =SUMIF($E$10:$E$97,"FT",R10:R97) -> 48 | S4: Full time | U4: =SUMIF($E$10:$E$97,"FT",U10:U97) -> 24 | V4: Full time | X4: =SUMIF($E$10:$E$97,"FT",X10:X97) -> 16 | Y4: Full time | AA4: =SUMIF($E$10:$E$97,"FT",AA10:AA97) -> 24
G5: Part time | I5: =SUMIF($E$10:$E$97,"PT",I10:I97) -> 30.5 | J5: Part time | L5: =SUMIF($E$10:$E$97,"PT",L10:L97) -> 30.5 | M5: Part time | O5: =SUMIF($E$10:$E$97,"PT",O10:O97) -> 54.5 | P5: Part time | R5: =SUMIF($E$10:$E$97,"PT",R10:R97) -> 62.5 | S5: Part time | U5: =SUMIF($E$10:$E$97,"PT",U10:U97) -> 61.5 | V5: Part time | X5: =SUMIF($E$10:$E$97,"PT",X10:X97) -> 32 | Y5: Part time | AA5: =SUMIF($E$10:$E$97,"PT",AA10:AA97) -> 64
G6: Casual | I6: =SUMIF($E$10:$E$97,"Cas",I10:I97) -> 45.5 | J6: Casual | L6: =SUMIF($E$10:$E$97,"Cas",L10:L97) -> 16 | M6: Casual | O6: =SUMIF($E$10:$E$97,"Cas",O10:O97) -> 8 | P6: Casual | R6: =SUMIF($E$10:$E$97,"Cas",R10:R97) -> 13 | S6: Casual | U6: =SUMIF($E$10:$E$97,"Cas",U10:U97) -> 45 | V6: Casual | X6: =SUMIF($E$10:$E$97,"Cas",X10:X97) -> 50 | Y6: Casual | AA6: =SUMIF($E$10:$E$97,"Cas",AA10:AA97) -> 45
G7: Total man hour | I7: =SUM(I10:I36) -> 53 | J7: Total man hour | L7: =SUM(L10:L36) -> 54.5 | M7: Total man hour | O7: =SUM(O10:O36) -> 70.5 | P7: Total man hour | R7: =SUM(R10:R36) -> 67.5 | S7: Total man hour | U7: =SUM(U10:U36) -> 43.5 | V7: Total man hour | X7: =SUM(X10:X36) -> 50 | Y7: Total man hour | AA7: =SUM(AA10:AA36) -> 93
B8: ID | C8: First Name | D8: Last Name | E8: Contract | F8: Hrs | G8: Start | H8: End | J8: Start | K8: End | M8: Start | N8: End | P8: Start | Q8: End | S8: Start | T8: End | V8: Start | W8: End | Y8: Start | Z8: End
B9: ='paste report'!A9 -> 01509 | C9: ='paste report'!B9 -> Amy | D9: ='paste report'!C9 -> Somana | E9: =VLOOKUP(B9,Team!$B$4:$F$183,5,FALSE) -> FT | F9: =I9+L9+O9+R9+U9+X9+AA9 -> 40.5 | G9: =_xlfn.IFNA(VLOOKUP(LEFT('paste report'!E9,6),$AE$10:$AF$47,2,FALSE),"") | H9: =_xlfn.IFNA(VLOOKUP(RIGHT('paste report'!E9,6),$AE$10:$AF$47,2,FALSE),"") | I9: =IFERROR(24*IF(H9>0,H9-G9,0),0) -> 0 | J9: =_xlfn.IFNA(VLOOKUP(LEFT('paste report'!F9,6),$AE$10:$AF$47,2,FALSE),"") -> 0.35416667 | K9: =_xlfn.IFNA(VLOOKUP(RIGHT('paste report'!F9,6),$AE$10:$AF$47,2,FALSE),"") -> 0.6875 | L9: =IFERROR(24*IF(K9>0,K9-J9,0),0) -> 8 | M9: =_xlfn.IFNA(VLOOKUP(LEFT('paste report'!G9,6),$AE$10:$AF$47,2,FALSE),"") -> 0.35416667 | N9: =_xlfn.IFNA(VLOOKUP(RIGHT('paste report'!G9,6),$AE$10:$AF$47,2,FALSE),"") -> 0.6875 | O9: =IFERROR(24*IF(N9>0,N9-M9,0),0) -> 8 | P9: =_xlfn.IFNA(VLOOKUP(LEFT('paste report'!H9,6),$AE$10:$AF$47,2,FALSE),"") -> 0.35416667 | Q9: =_xlfn.IFNA(VLOOKUP(RIGHT('paste report'!H9,6),$AE$10:$AF$47,2,FALSE),"") -> 0.70833333 | R9: =IFERROR(24*IF(Q9>0,Q9-P9,0),0) -> 8.5 | S9: =_xlfn.IFNA(VLOOKUP(LEFT('paste report'!I9,6),$AE$10:$AF$47,2,FALSE),"") -> 0.35416667 | T9: =_xlfn.IFNA(VLOOKUP(RIGHT('paste report'!I9,6),$AE$10:$AF$47,2,FALSE),"") -> 0.6875 | U9: =IFERROR(24*IF(T9>0,T9-S9,0),0) -> 8 | V9: =_xlfn.IFNA(VLOOKUP(LEFT('paste report'!J9,6),$AE$10:$AF$47,2,FALSE),"") -> 0.5 | W9: =_xlfn.IFNA(VLOOKUP(RIGHT('paste report'!J9,6),$AE$10:$AF$47,2,FALSE),"") -> 0.83333333 | X9: =IFERROR(24*IF(W9>0,W9-V9,0),0) -> 8 | Y9: =_xlfn.IFNA(VLOOKUP(LEFT('paste report'!K9,6),$AE$10:$AF$47,2,FALSE),"") | Z9: =_xlfn.IFNA(VLOOKUP(RIGHT('paste report'!K9,6),$AE$10:$AF$47,2,FALSE),"") | AA9: =IFERROR(24*IF(Z9>0,Z9-Y9,0),0) -> 0
B10: ='paste report'!A10 -> 1175 | C10: ='paste report'!B10 -> Anna | D10: ='paste report'!C10 -> Naritsuka-Hayler | E10: =VLOOKUP(B10,Team!$B$4:$F$183,5,FALSE) -> PT | F10: =I10+L10+O10+R10+U10+X10+AA10 -> 24 | G10: =_xlfn.IFNA(VLOOKUP(LEFT('paste report'!E10,6),$AE$10:$AF$47,2,FALSE),"") | H10: =_xlfn.IFNA(VLOOKUP(RIGHT('paste report'!E10,6),$AE$10:$AF$47,2,FALSE),"") | I10: =IFERROR(24*IF(H10>0,H10-G10,0),0) -> 0 | J10: =_xlfn.IFNA(VLOOKUP(LEFT('paste report'!F10,6),$AE$10:$AF$47,2,FALSE),"") -> 0.35416667 | K10: =_xlfn.IFNA(VLOOKUP(RIGHT('paste report'!F10,6),$AE$10:$AF$47,2,FALSE),"") -> 0.6875 | L10: =IFERROR(24*IF(K10>0,K10-J10,0),0) -> 8 | M10: =_xlfn.IFNA(VLOOKUP(LEFT('paste report'!G10,6),$AE$10:$AF$47,2,FALSE),"") -> 0.35416667 | N10: =_xlfn.IFNA(VLOOKUP(RIGHT('paste report'!G10,6),$AE$10:$AF$47,2,FALSE),"") -> 0.6875 | O10: =IFERROR(24*IF(N10>0,N10-M10,0),0) -> 8 | P10: =_xlfn.IFNA(VLOOKUP(LEFT('paste report'!H10,6),$AE$10:$AF$47,2,FALSE),"") | Q10: =_xlfn.IFNA(VLOOKUP(RIGHT('paste report'!H10,6),$AE$10:$AF$47,2,FALSE),"") | R10: =IFERROR(24*IF(Q10>0,Q10-P10,0),0) -> 0 | S10: =_xlfn.IFNA(VLOOKUP(LEFT('paste report'!I10,6),$AE$10:$AF$47,2,FALSE),"") | T10: =_xlfn.IFNA(VLOOKUP(RIGHT('paste report'!I10,6),$AE$10:$AF$47,2,FALSE),"") | U10: =IFERROR(24*IF(T10>0,T10-S10,0),0) -> 0 | V10: =_xlfn.IFNA(VLOOKUP(LEFT('paste report'!J10,6),$AE$10:$AF$47,2,FALSE),"") | W10: =_xlfn.IFNA(VLOOKUP(RIGHT('paste report'!J10,6),$AE$10:$AF$47,2,FALSE),"") | X10: =IFERROR(24*IF(W10>0,W10-V10,0),0) -> 0 | Y10: =_xlfn.IFNA(VLOOKUP(LEFT('paste report'!K10,6),$AE$10:$AF$47,2,FALSE),"") -> 0.5 | Z10: =_xlfn.IFNA(VLOOKUP(RIGHT('paste report'!K10,6),$AE$10:$AF$47,2,FALSE),"") -> 0.83333333 | AA10: =IFERROR(24*IF(Z10>0,Z10-Y10,0),0) -> 8 | AE10: 05:00a | AF10: 0.20833333
B11: ='paste report'!A11 -> 1041 | C11: ='paste report'!B11 -> Archana | D11: ='paste report'!C11 -> Prashanth | E11: =VLOOKUP(B11,Team!$B$4:$F$183,5,FALSE) -> CAS | F11: =I11+L11+O11+R11+U11+X11+AA11 -> 0 | G11: =_xlfn.IFNA(VLOOKUP(LEFT('paste report'!E11,6),$AE$10:$AF$47,2,FALSE),"") | H11: =_xlfn.IFNA(VLOOKUP(RIGHT('paste report'!E11,6),$AE$10:$AF$47,2,FALSE),"") | I11: =IFERROR(24*IF(H11>0,H11-G11,0),0) -> 0 | J11: =_xlfn.IFNA(VLOOKUP(LEFT('paste report'!F11,6),$AE$10:$AF$47,2,FALSE),"") | K11: =_xlfn.IFNA(VLOOKUP(RIGHT('paste report'!F11,6),$AE$10:$AF$47,2,FALSE),"") | L11: =IFERROR(24*IF(K11>0,K11-J11,0),0) -> 0 | M11: =_xlfn.IFNA(VLOOKUP(LEFT('paste report'!G11,6),$AE$10:$AF$47,2,FALSE),"") | N11: =_xlfn.IFNA(VLOOKUP(RIGHT('paste report'!G11,6),$AE$10:$AF$47,2,FALSE),"") | O11: =IFERROR(24*IF(N11>0,N11-M11,0),0) -> 0 | P11: =_xlfn.IFNA(VLOOKUP(LEFT('paste report'!H11,6),$AE$10:$AF$47,2,FALSE),"") | Q11: =_xlfn.IFNA(VLOOKUP(RIGHT('paste report'!H11,6),$AE$10:$AF$47,2,FALSE),"") | R11: =IFERROR(24*IF(Q11>0,Q11-P11,0),0) -> 0 | S11: =_xlfn.IFNA(VLOOKUP(LEFT('paste report'!I11,6),$AE$10:$AF$47,2,FALSE),"") | T11: =_xlfn.IFNA(VLOOKUP(RIGHT('paste report'!I11,6),$AE$10:$AF$47,2,FALSE),"") | U11: =IFERROR(24*IF(T11>0,T11-S11,0),0) -> 0 | V11: =_xlfn.IFNA(VLOOKUP(LEFT('paste report'!J11,6),$AE$10:$AF$47,2,FALSE),"") | W11: =_xlfn.IFNA(VLOOKUP(RIGHT('paste report'!J11,6),$AE$10:$AF$47,2,FALSE),"") | X11: =IFERROR(24*IF(W11>0,W11-V11,0),0) -> 0 | Y11: =_xlfn.IFNA(VLOOKUP(LEFT('paste report'!K11,6),$AE$10:$AF$47,2,FALSE),"") | Z11: =_xlfn.IFNA(VLOOKUP(RIGHT('paste report'!K11,6),$AE$10:$AF$47,2,FALSE),"") | AA11: =IFERROR(24*IF(Z11>0,Z11-Y11,0),0) -> 0 | AE11: 05:30a | AF11: 0.22916667
B12: ='paste report'!A12 -> 1245 | C12: ='paste report'!B12 -> Charlotte | D12: ='paste report'!C12 -> Robertson | E12: =VLOOKUP(B12,Team!$B$4:$F$183,5,FALSE) -> CAS | F12: =I12+L12+O12+R12+U12+X12+AA12 -> 0 | G12: =_xlfn.IFNA(VLOOKUP(LEFT('paste report'!E12,6),$AE$10:$AF$47,2,FALSE),"") | H12: =_xlfn.IFNA(VLOOKUP(RIGHT('paste report'!E12,6),$AE$10:$AF$47,2,FALSE),"") | I12: =IFERROR(24*IF(H12>0,H12-G12,0),0) -> 0 | J12: =_xlfn.IFNA(VLOOKUP(LEFT('paste report'!F12,6),$AE$10:$AF$47,2,FALSE),"") | K12: =_xlfn.IFNA(VLOOKUP(RIGHT('paste report'!F12,6),$AE$10:$AF$47,2,FALSE),"") | L12: =IFERROR(24*IF(K12>0,K12-J12,0),0) -> 0 | M12: =_xlfn.IFNA(VLOOKUP(LEFT('paste report'!G12,6),$AE$10:$AF$47,2,FALSE),"") | N12: =_xlfn.IFNA(VLOOKUP(RIGHT('paste report'!G12,6),$AE$10:$AF$47,2,FALSE),"") | O12: =IFERROR(24*IF(N12>0,N12-M12,0),0) -> 0 | P12: =_xlfn.IFNA(VLOOKUP(LEFT('paste report'!H12,6),$AE$10:$AF$47,2,FALSE),"") | Q12: =_xlfn.IFNA(VLOOKUP(RIGHT('paste report'!H12,6),$AE$10:$AF$47,2,FALSE),"") | R12: =IFERROR(24*IF(Q12>0,Q12-P12,0),0) -> 0 | S12: =_xlfn.IFNA(VLOOKUP(LEFT('paste report'!I12,6),$AE$10:$AF$47,2,FALSE),"") | T12: =_xlfn.IFNA(VLOOKUP(RIGHT('paste report'!I12,6),$AE$10:$AF$47,2,FALSE),"") | U12: =IFERROR(24*IF(T12>0,T12-S12,0),0) -> 0 | V12: =_xlfn.IFNA(VLOOKUP(LEFT('paste report'!J12,6),$AE$10:$AF$47,2,FALSE),"") | W12: =_xlfn.IFNA(VLOOKUP(RIGHT('paste report'!J12,6),$AE$10:$AF$47,2,FALSE),"") | X12: =IFERROR(24*IF(W12>0,W12-V12,0),0) -> 0 | Y12: =_xlfn.IFNA(VLOOKUP(LEFT('paste report'!K12,6),$AE$10:$AF$47,2,FALSE),"") | Z12: =_xlfn.IFNA(VLOOKUP(RIGHT('paste report'!K12,6),$AE$10:$AF$47,2,FALSE),"") | AA12: =IFERROR(24*IF(Z12>0,Z12-Y12,0),0) -> 0 | AE12: 06:00a | AF12: 0.25
B13: ='paste report'!A13 -> 1136 | C13: ='paste report'!B13 -> Cherry | D13: ='paste report'!C13 -> Ward | E13: =VLOOKUP(B13,Team!$B$4:$F$183,5,FALSE) -> PT | F13: =I13+L13+O13+R13+U13+X13+AA13 -> 24 | G13: =_xlfn.IFNA(VLOOKUP(LEFT('paste report'!E13,6),$AE$10:$AF$47,2,FALSE),"") | H13: =_xlfn.IFNA(VLOOKUP(RIGHT('paste report'!E13,6),$AE$10:$AF$47,2,FALSE),"") | I13: =IFERROR(24*IF(H13>0,H13-G13,0),0) -> 0 | J13: =_xlfn.IFNA(VLOOKUP(LEFT('paste report'!F13,6),$AE$10:$AF$47,2,FALSE),"") | K13: =_xlfn.IFNA(VLOOKUP(RIGHT('paste report'!F13,6),$AE$10:$AF$47,2,FALSE),"") | L13: =IFERROR(24*IF(K13>0,K13-J13,0),0) -> 0 | M13: =_xlfn.IFNA(VLOOKUP(LEFT('paste report'!G13,6),$AE$10:$AF$47,2,FALSE),"") -> 0.45833333 | N13: =_xlfn.IFNA(VLOOKUP(RIGHT('paste report'!G13,6),$AE$10:$AF$47,2,FALSE),"") -> 0.79166667 | O13: =IFERROR(24*IF(N13>0,N13-M13,0),0) -> 8 | P13: =_xlfn.IFNA(VLOOKUP(LEFT('paste report'!H13,6),$AE$10:$AF$47,2,FALSE),"") | Q13: =_xlfn.IFNA(VLOOKUP(RIGHT('paste report'!H13,6),$AE$10:$AF$47,2,FALSE),"") | R13: =IFERROR(24*IF(Q13>0,Q13-P13,0),0) -> 0 | S13: =_xlfn.IFNA(VLOOKUP(LEFT('paste report'!I13,6),$AE$10:$AF$47,2,FALSE),"") -> 0.45833333 | T13: =_xlfn.IFNA(VLOOKUP(RIGHT('paste report'!I13,6),$AE$10:$AF$47,2,FALSE),"") -> 0.79166667 | U13: =IFERROR(24*IF(T13>0,T13-S13,0),0) -> 8 | V13: =_xlfn.IFNA(VLOOKUP(LEFT('paste report'!J13,6),$AE$10:$AF$47,2,FALSE),"") | W13: =_xlfn.IFNA(VLOOKUP(RIGHT('paste report'!J13,6),$AE$10:$AF$47,2,FALSE),"") | X13: =IFERROR(24*IF(W13>0,W13-V13,0),0) -> 0 | Y13: =_xlfn.IFNA(VLOOKUP(LEFT('paste report'!K13,6),$AE$10:$AF$47,2,FALSE),"") -> 0.5 | Z13: =_xlfn.IFNA(VLOOKUP(RIGHT('paste report'!K13,6),$AE$10:$AF$47,2,FALSE),"") -> 0.83333333 | AA13: =IFERROR(24*IF(Z13>0,Z13-Y13,0),0) -> 8 | AE13: 06:30a | AF13: 0.27083333
B14: ='paste report'!A14 -> 1247 | C14: ='paste report'!B14 -> Chihiro | D14: ='paste report'!C14 -> Burgoyne | E14: =VLOOKUP(B14,Team!$B$4:$F$183,5,FALSE) -> PT | F14: =I14+L14+O14+R14+U14+X14+AA14 -> 32.5 | G14: =_xlfn.IFNA(VLOOKUP(LEFT('paste report'!E14,6),$AE$10:$AF$47,2,FALSE),"") -> 0.35416667 | H14: =_xlfn.IFNA(VLOOKUP(RIGHT('paste report'!E14,6),$AE$10:$AF$47,2,FALSE),"") -> 0.625 | I14: =IFERROR(24*IF(H14>0,H14-G14,0),0) -> 6.5 | J14: =_xlfn.IFNA(VLOOKUP(LEFT('paste report'!F14,6),$AE$10:$AF$47,2,FALSE),"") -> 0.35416667 | K14: =_xlfn.IFNA(VLOOKUP(RIGHT('paste report'!F14,6),$AE$10:$AF$47,2,FALSE),"") -> 0.625 | L14: =IFERROR(24*IF(K14>0,K14-J14,0),0) -> 6.5 | M14: =_xlfn.IFNA(VLOOKUP(LEFT('paste report'!G14,6),$AE$10:$AF$47,2,FALSE),"") -> 0.35416667 | N14: =_xlfn.IFNA(VLOOKUP(RIGHT('paste report'!G14,6),$AE$10:$AF$47,2,FALSE),"") -> 0.625 | O14: =IFERROR(24*IF(N14>0,N14-M14,0),0) -> 6.5 | P14: =_xlfn.IFNA(VLOOKUP(LEFT('paste report'!H14,6),$AE$10:$AF$47,2,FALSE),"") -> 0.35416667 | Q14: =_xlfn.IFNA(VLOOKUP(RIGHT('paste report'!H14,6),$AE$10:$AF$47,2,FALSE),"") -> 0.625 | R14: =IFERROR(24*IF(Q14>0,Q14-P14,0),0) -> 6.5 | S14: =_xlfn.IFNA(VLOOKUP(LEFT('paste report'!I14,6),$AE$10:$AF$47,2,FALSE),"") -> 0.35416667 | T14: =_xlfn.IFNA(VLOOKUP(RIGHT('paste report'!I14,6),$AE$10:$AF$47,2,FALSE),"") -> 0.625 | U14: =IFERROR(24*IF(T14>0,T14-S14,0),0) -> 6.5 | V14: =_xlfn.IFNA(VLOOKUP(LEFT('paste report'!J14,6),$AE$10:$AF$47,2,FALSE),"") | W14: =_xlfn.IFNA(VLOOKUP(RIGHT('paste report'!J14,6),$AE$10:$AF$47,2,FALSE),"") | X14: =IFERROR(24*IF(W14>0,W14-V14,0),0) -> 0 | Y14: =_xlfn.IFNA(VLOOKUP(LEFT('paste report'!K14,6),$AE$10:$AF$47,2,FALSE),"") | Z14: =_xlfn.IFNA(VLOOKUP(RIGHT('paste report'!K14,6),$AE$10:$AF$47,2,FALSE),"") | AA14: =IFERROR(24*IF(Z14>0,Z14-Y14,0),0) -> 0 | AE14: 07:00a | AF14: 0.29166667
B15: ='paste report'!A15 -> 01514 | C15: ='paste report'!B15 -> Chloe | D15: ='paste report'!C15 -> Huang | E15: =VLOOKUP(B15,Team!$B$4:$F$183,5,FALSE) -> FT | F15: =I15+L15+O15+R15+U15+X15+AA15 -> 40.5 | G15: =_xlfn.IFNA(VLOOKUP(LEFT('paste report'!E15,6),$AE$10:$AF$47,2,FALSE),"") -> 0.4375 | H15: =_xlfn.IFNA(VLOOKUP(RIGHT('paste report'!E15,6),$AE$10:$AF$47,2,FALSE),"") -> 0.79166667 | I15: =IFERROR(24*IF(H15>0,H15-G15,0),0) -> 8.5 | J15: =_xlfn.IFNA(VLOOKUP(LEFT('paste report'!F15,6),$AE$10:$AF$47,2,FALSE),"") -> 0.45833333 | K15: =_xlfn.IFNA(VLOOKUP(RIGHT('paste report'!F15,6),$AE$10:$AF$47,2,FALSE),"") -> 0.79166667 | L15: =IFERROR(24*IF(K15>0,K15-J15,0),0) -> 8 | M15: =_xlfn.IFNA(VLOOKUP(LEFT('paste report'!G15,6),$AE$10:$AF$47,2,FALSE),"") -> 0.45833333 | N15: =_xlfn.IFNA(VLOOKUP(RIGHT('paste report'!G15,6),$AE$10:$AF$47,2,FALSE),"") -> 0.79166667 | O15: =IFERROR(24*IF(N15>0,N15-M15,0),0) -> 8 | P15: =_xlfn.IFNA(VLOOKUP(LEFT('paste report'!H15,6),$AE$10:$AF$47,2,FALSE),"") -> 0.58333333 | Q15: =_xlfn.IFNA(VLOOKUP(RIGHT('paste report'!H15,6),$AE$10:$AF$47,2,FALSE),"") -> 0.91666667 | R15: =IFERROR(24*IF(Q15>0,Q15-P15,0),0) -> 8 | S15: =_xlfn.IFNA(VLOOKUP(LEFT('paste report'!I15,6),$AE$10:$AF$47,2,FALSE),"") | T15: =_xlfn.IFNA(VLOOKUP(RIGHT('paste report'!I15,6),$AE$10:$AF$47,2,FALSE),"") | U15: =IFERROR(24*IF(T15>0,T15-S15,0),0) -> 0 | V15: =_xlfn.IFNA(VLOOKUP(LEFT('paste report'!J15,6),$AE$10:$AF$47,2,FALSE),"") | W15: =_xlfn.IFNA(VLOOKUP(RIGHT('paste report'!J15,6),$AE$10:$AF$47,2,FALSE),"") | X15: =IFERROR(24*IF(W15>0,W15-V15,0),0) -> 0 | Y15: =_xlfn.IFNA(VLOOKUP(LEFT('paste report'!K15,6),$AE$10:$AF$47,2,FALSE),"") -> 0.5 | Z15: =_xlfn.IFNA(VLOOKUP(RIGHT('paste report'!K15,6),$AE$10:$AF$47,2,FALSE),"") -> 0.83333333 | AA15: =IFERROR(24*IF(Z15>0,Z15-Y15,0),0) -> 8 | AE15: 07:30a | AF15: 0.3125
B16: ='paste report'!A16 -> 660 | C16: ='paste report'!B16 -> Daniel | D16: ='paste report'!C16 -> Park | E16: =VLOOKUP(B16,Team!$B$4:$F$183,5,FALSE) -> CAS | F16: =I16+L16+O16+R16+U16+X16+AA16 -> 0 | G16: =_xlfn.IFNA(VLOOKUP(LEFT('paste report'!E16,6),$AE$10:$AF$47,2,FALSE),"") | H16: =_xlfn.IFNA(VLOOKUP(RIGHT('paste report'!E16,6),$AE$10:$AF$47,2,FALSE),"") | I16: =IFERROR(24*IF(H16>0,H16-G16,0),0) -> 0 | J16: =_xlfn.IFNA(VLOOKUP(LEFT('paste report'!F16,6),$AE$10:$AF$47,2,FALSE),"") | K16: =_xlfn.IFNA(VLOOKUP(RIGHT('paste report'!F16,6),$AE$10:$AF$47,2,FALSE),"") | L16: =IFERROR(24*IF(K16>0,K16-J16,0),0) -> 0 | M16: =_xlfn.IFNA(VLOOKUP(LEFT('paste report'!G16,6),$AE$10:$AF$47,2,FALSE),"") | N16: =_xlfn.IFNA(VLOOKUP(RIGHT('paste report'!G16,6),$AE$10:$AF$47,2,FALSE),"") | O16: =IFERROR(24*IF(N16>0,N16-M16,0),0) -> 0 | P16: =_xlfn.IFNA(VLOOKUP(LEFT('paste report'!H16,6),$AE$10:$AF$47,2,FALSE),"") | Q16: =_xlfn.IFNA(VLOOKUP(RIGHT('paste report'!H16,6),$AE$10:$AF$47,2,FALSE),"") | R16: =IFERROR(24*IF(Q16>0,Q16-P16,0),0) -> 0 | S16: =_xlfn.IFNA(VLOOKUP(LEFT('paste report'!I16,6),$AE$10:$AF$47,2,FALSE),"") | T16: =_xlfn.IFNA(VLOOKUP(RIGHT('paste report'!I16,6),$AE$10:$AF$47,2,FALSE),"") | U16: =IFERROR(24*IF(T16>0,T16-S16,0),0) -> 0 | V16: =_xlfn.IFNA(VLOOKUP(LEFT('paste report'!J16,6),$AE$10:$AF$47,2,FALSE),"") | W16: =_xlfn.IFNA(VLOOKUP(RIGHT('paste report'!J16,6),$AE$10:$AF$47,2,FALSE),"") | X16: =IFERROR(24*IF(W16>0,W16-V16,0),0) -> 0 | Y16: =_xlfn.IFNA(VLOOKUP(LEFT('paste report'!K16,6),$AE$10:$AF$47,2,FALSE),"") | Z16: =_xlfn.IFNA(VLOOKUP(RIGHT('paste report'!K16,6),$AE$10:$AF$47,2,FALSE),"") | AA16: =IFERROR(24*IF(Z16>0,Z16-Y16,0),0) -> 0 | AE16: 08:00a | AF16: 0.33333333
B17: ='paste report'!A17 -> 1275 | C17: ='paste report'!B17 -> Da-yeon | D17: ='paste report'!C17 -> Oh | E17: =VLOOKUP(B17,Team!$B$4:$F$183,5,FALSE) -> CAS | F17: =I17+L17+O17+R17+U17+X17+AA17 -> 0 | G17: =_xlfn.IFNA(VLOOKUP(LEFT('paste report'!E17,6),$AE$10:$AF$47,2,FALSE),"") | H17: =_xlfn.IFNA(VLOOKUP(RIGHT('paste report'!E17,6),$AE$10:$AF$47,2,FALSE),"") | I17: =IFERROR(24*IF(H17>0,H17-G17,0),0) -> 0 | J17: =_xlfn.IFNA(VLOOKUP(LEFT('paste report'!F17,6),$AE$10:$AF$47,2,FALSE),"") | K17: =_xlfn.IFNA(VLOOKUP(RIGHT('paste report'!F17,6),$AE$10:$AF$47,2,FALSE),"") | L17: =IFERROR(24*IF(K17>0,K17-J17,0),0) -> 0 | M17: =_xlfn.IFNA(VLOOKUP(LEFT('paste report'!G17,6),$AE$10:$AF$47,2,FALSE),"") | N17: =_xlfn.IFNA(VLOOKUP(RIGHT('paste report'!G17,6),$AE$10:$AF$47,2,FALSE),"") | O17: =IFERROR(24*IF(N17>0,N17-M17,0),0) -> 0 | P17: =_xlfn.IFNA(VLOOKUP(LEFT('paste report'!H17,6),$AE$10:$AF$47,2,FALSE),"") | Q17: =_xlfn.IFNA(VLOOKUP(RIGHT('paste report'!H17,6),$AE$10:$AF$47,2,FALSE),"") | R17: =IFERROR(24*IF(Q17>0,Q17-P17,0),0) -> 0 | S17: =_xlfn.IFNA(VLOOKUP(LEFT('paste report'!I17,6),$AE$10:$AF$47,2,FALSE),"") | T17: =_xlfn.IFNA(VLOOKUP(RIGHT('paste report'!I17,6),$AE$10:$AF$47,2,FALSE),"") | U17: =IFERROR(24*IF(T17>0,T17-S17,0),0) -> 0 | V17: =_xlfn.IFNA(VLOOKUP(LEFT('paste report'!J17,6),$AE$10:$AF$47,2,FALSE),"") | W17: =_xlfn.IFNA(VLOOKUP(RIGHT('paste report'!J17,6),$AE$10:$AF$47,2,FALSE),"") | X17: =IFERROR(24*IF(W17>0,W17-V17,0),0) -> 0 | Y17: =_xlfn.IFNA(VLOOKUP(LEFT('paste report'!K17,6),$AE$10:$AF$47,2,FALSE),"") | Z17: =_xlfn.IFNA(VLOOKUP(RIGHT('paste report'!K17,6),$AE$10:$AF$47,2,FALSE),"") | AA17: =IFERROR(24*IF(Z17>0,Z17-Y17,0),0) -> 0 | AE17: 08:30a | AF17: 0.35416667
B18: ='paste report'!A18 -> 1258 | C18: ='paste report'!B18 -> Dennis | D18: ='paste report'!C18 -> Kim | E18: =VLOOKUP(B18,Team!$B$4:$F$183,5,FALSE) -> CAS | F18: =I18+L18+O18+R18+U18+X18+AA18 -> 5 | G18: =_xlfn.IFNA(VLOOKUP(LEFT('paste report'!E18,6),$AE$10:$AF$47,2,FALSE),"") | H18: =_xlfn.IFNA(VLOOKUP(RIGHT('paste report'!E18,6),$AE$10:$AF$47,2,FALSE),"") | I18: =IFERROR(24*IF(H18>0,H18-G18,0),0) -> 0 | J18: =_xlfn.IFNA(VLOOKUP(LEFT('paste report'!F18,6),$AE$10:$AF$47,2,FALSE),"") | K18: =_xlfn.IFNA(VLOOKUP(RIGHT('paste report'!F18,6),$AE$10:$AF$47,2,FALSE),"") | L18: =IFERROR(24*IF(K18>0,K18-J18,0),0) -> 0 | M18: =_xlfn.IFNA(VLOOKUP(LEFT('paste report'!G18,6),$AE$10:$AF$47,2,FALSE),"") | N18: =_xlfn.IFNA(VLOOKUP(RIGHT('paste report'!G18,6),$AE$10:$AF$47,2,FALSE),"") | O18: =IFERROR(24*IF(N18>0,N18-M18,0),0) -> 0 | P18: =_xlfn.IFNA(VLOOKUP(LEFT('paste report'!H18,6),$AE$10:$AF$47,2,FALSE),"") | Q18: =_xlfn.IFNA(VLOOKUP(RIGHT('paste report'!H18,6),$AE$10:$AF$47,2,FALSE),"") | R18: =IFERROR(24*IF(Q18>0,Q18-P18,0),0) -> 0 | S18: =_xlfn.IFNA(VLOOKUP(LEFT('paste report'!I18,6),$AE$10:$AF$47,2,FALSE),"") | T18: =_xlfn.IFNA(VLOOKUP(RIGHT('paste report'!I18,6),$AE$10:$AF$47,2,FALSE),"") | U18: =IFERROR(24*IF(T18>0,T18-S18,0),0) -> 0 | V18: =_xlfn.IFNA(VLOOKUP(LEFT('paste report'!J18,6),$AE$10:$AF$47,2,FALSE),"") -> 0.625 | W18: =_xlfn.IFNA(VLOOKUP(RIGHT('paste report'!J18,6),$AE$10:$AF$47,2,FALSE),"") -> 0.83333333 | X18: =IFERROR(24*IF(W18>0,W18-V18,0),0) -> 5 | Y18: =_xlfn.IFNA(VLOOKUP(LEFT('paste report'!K18,6),$AE$10:$AF$47,2,FALSE),"") | Z18: =_xlfn.IFNA(VLOOKUP(RIGHT('paste report'!K18,6),$AE$10:$AF$47,2,FALSE),"") | AA18: =IFERROR(24*IF(Z18>0,Z18-Y18,0),0) -> 0 | AE18: 09:00a | AF18: 0.375
B19: ='paste report'!A19 -> 1131 | C19: ='paste report'!B19 -> Doris | D19: ='paste report'!C19 -> Hou | E19: =VLOOKUP(B19,Team!$B$4:$F$183,5,FALSE) -> CAS | F19: =I19+L19+O19+R19+U19+X19+AA19 -> 0 | G19: =_xlfn.IFNA(VLOOKUP(LEFT('paste report'!E19,6),$AE$10:$AF$47,2,FALSE),"") | H19: =_xlfn.IFNA(VLOOKUP(RIGHT('paste report'!E19,6),$AE$10:$AF$47,2,FALSE),"") | I19: =IFERROR(24*IF(H19>0,H19-G19,0),0) -> 0 | J19: =_xlfn.IFNA(VLOOKUP(LEFT('paste report'!F19,6),$AE$10:$AF$47,2,FALSE),"") | K19: =_xlfn.IFNA(VLOOKUP(RIGHT('paste report'!F19,6),$AE$10:$AF$47,2,FALSE),"") | L19: =IFERROR(24*IF(K19>0,K19-J19,0),0) -> 0 | M19: =_xlfn.IFNA(VLOOKUP(LEFT('paste report'!G19,6),$AE$10:$AF$47,2,FALSE),"") | N19: =_xlfn.IFNA(VLOOKUP(RIGHT('paste report'!G19,6),$AE$10:$AF$47,2,FALSE),"") | O19: =IFERROR(24*IF(N19>0,N19-M19,0),0) -> 0 | P19: =_xlfn.IFNA(VLOOKUP(LEFT('paste report'!H19,6),$AE$10:$AF$47,2,FALSE),"") | Q19: =_xlfn.IFNA(VLOOKUP(RIGHT('paste report'!H19,6),$AE$10:$AF$47,2,FALSE),"") | R19: =IFERROR(24*IF(Q19>0,Q19-P19,0),0) -> 0 | S19: =_xlfn.IFNA(VLOOKUP(LEFT('paste report'!I19,6),$AE$10:$AF$47,2,FALSE),"") | T19: =_xlfn.IFNA(VLOOKUP(RIGHT('paste report'!I19,6),$AE$10:$AF$47,2,FALSE),"") | U19: =IFERROR(24*IF(T19>0,T19-S19,0),0) -> 0 | V19: =_xlfn.IFNA(VLOOKUP(LEFT('paste report'!J19,6),$AE$10:$AF$47,2,FALSE),"") | W19: =_xlfn.IFNA(VLOOKUP(RIGHT('paste report'!J19,6),$AE$10:$AF$47,2,FALSE),"") | X19: =IFERROR(24*IF(W19>0,W19-V19,0),0) -> 0 | Y19: =_xlfn.IFNA(VLOOKUP(LEFT('paste report'!K19,6),$AE$10:$AF$47,2,FALSE),"") | Z19: =_xlfn.IFNA(VLOOKUP(RIGHT('paste report'!K19,6),$AE$10:$AF$47,2,FALSE),"") | AA19: =IFERROR(24*IF(Z19>0,Z19-Y19,0),0) -> 0 | AE19: 09:30a | AF19: 0.39583333
B20: ='paste report'!A20 -> 01601 | C20: ='paste report'!B20 -> Dorothy | D20: ='paste report'!C20 -> Choi | E20: =VLOOKUP(B20,Team!$B$4:$F$183,5,FALSE) -> CAS | F20: =I20+L20+O20+R20+U20+X20+AA20 -> 8 | G20: =_xlfn.IFNA(VLOOKUP(LEFT('paste report'!E20,6),$AE$10:$AF$47,2,FALSE),"") | H20: =_xlfn.IFNA(VLOOKUP(RIGHT('paste report'!E20,6),$AE$10:$AF$47,2,FALSE),"") | I20: =IFERROR(24*IF(H20>0,H20-G20,0),0) -> 0 | J20: =_xlfn.IFNA(VLOOKUP(LEFT('paste report'!F20,6),$AE$10:$AF$47,2,FALSE),"") | K20: =_xlfn.IFNA(VLOOKUP(RIGHT('paste report'!F20,6),$AE$10:$AF$47,2,FALSE),"") | L20: =IFERROR(24*IF(K20>0,K20-J20,0),0) -> 0 | M20: =_xlfn.IFNA(VLOOKUP(LEFT('paste report'!G20,6),$AE$10:$AF$47,2,FALSE),"") | N20: =_xlfn.IFNA(VLOOKUP(RIGHT('paste report'!G20,6),$AE$10:$AF$47,2,FALSE),"") | O20: =IFERROR(24*IF(N20>0,N20-M20,0),0) -> 0 | P20: =_xlfn.IFNA(VLOOKUP(LEFT('paste report'!H20,6),$AE$10:$AF$47,2,FALSE),"") | Q20: =_xlfn.IFNA(VLOOKUP(RIGHT('paste report'!H20,6),$AE$10:$AF$47,2,FALSE),"") | R20: =IFERROR(24*IF(Q20>0,Q20-P20,0),0) -> 0 | S20: =_xlfn.IFNA(VLOOKUP(LEFT('paste report'!I20,6),$AE$10:$AF$47,2,FALSE),"") | T20: =_xlfn.IFNA(VLOOKUP(RIGHT('paste report'!I20,6),$AE$10:$AF$47,2,FALSE),"") | U20: =IFERROR(24*IF(T20>0,T20-S20,0),0) -> 0 | V20: =_xlfn.IFNA(VLOOKUP(LEFT('paste report'!J20,6),$AE$10:$AF$47,2,FALSE),"") -> 0.45833333 | W20: =_xlfn.IFNA(VLOOKUP(RIGHT('paste report'!J20,6),$AE$10:$AF$47,2,FALSE),"") -> 0.79166667 | X20: =IFERROR(24*IF(W20>0,W20-V20,0),0) -> 8 | Y20: =_xlfn.IFNA(VLOOKUP(LEFT('paste report'!K20,6),$AE$10:$AF$47,2,FALSE),"") | Z20: =_xlfn.IFNA(VLOOKUP(RIGHT('paste report'!K20,6),$AE$10:$AF$47,2,FALSE),"") | AA20: =IFERROR(24*IF(Z20>0,Z20-Y20,0),0) -> 0 | AE20: 10:00a | AF20: 0.41666667
B21: ='paste report'!A21 -> 01506 | C21: ='paste report'!B21 -> Duke | D21: ='paste report'!C21 -> Trac | E21: =VLOOKUP(B21,Team!$B$4:$F$183,5,FALSE) -> PT | F21: =I21+L21+O21+R21+U21+X21+AA21 -> 24 | G21: =_xlfn.IFNA(VLOOKUP(LEFT('paste report'!E21,6),$AE$10:$AF$47,2,FALSE),"") | H21: =_xlfn.IFNA(VLOOKUP(RIGHT('paste report'!E21,6),$AE$10:$AF$47,2,FALSE),"") | I21: =IFERROR(24*IF(H21>0,H21-G21,0),0) -> 0 | J21: =_xlfn.IFNA(VLOOKUP(LEFT('paste report'!F21,6),$AE$10:$AF$47,2,FALSE),"") | K21: =_xlfn.IFNA(VLOOKUP(RIGHT('paste report'!F21,6),$AE$10:$AF$47,2,FALSE),"") | L21: =IFERROR(24*IF(K21>0,K21-J21,0),0) -> 0 | M21: =_xlfn.IFNA(VLOOKUP(LEFT('paste report'!G21,6),$AE$10:$AF$47,2,FALSE),"") | N21: =_xlfn.IFNA(VLOOKUP(RIGHT('paste report'!G21,6),$AE$10:$AF$47,2,FALSE),"") | O21: =IFERROR(24*IF(N21>0,N21-M21,0),0) -> 0 | P21: =_xlfn.IFNA(VLOOKUP(LEFT('paste report'!H21,6),$AE$10:$AF$47,2,FALSE),"") -> 0.58333333 | Q21: =_xlfn.IFNA(VLOOKUP(RIGHT('paste report'!H21,6),$AE$10:$AF$47,2,FALSE),"") -> 0.91666667 | R21: =IFERROR(24*IF(Q21>0,Q21-P21,0),0) -> 8 | S21: =_xlfn.IFNA(VLOOKUP(LEFT('paste report'!I21,6),$AE$10:$AF$47,2,FALSE),"") | T21: =_xlfn.IFNA(VLOOKUP(RIGHT('paste report'!I21,6),$AE$10:$AF$47,2,FALSE),"") | U21: =IFERROR(24*IF(T21>0,T21-S21,0),0) -> 0 | V21: =_xlfn.IFNA(VLOOKUP(LEFT('paste report'!J21,6),$AE$10:$AF$47,2,FALSE),"") -> 0.5 | W21: =_xlfn.IFNA(VLOOKUP(RIGHT('paste report'!J21,6),$AE$10:$AF$47,2,FALSE),"") -> 0.83333333 | X21: =IFERROR(24*IF(W21>0,W21-V21,0),0) -> 8 | Y21: =_xlfn.IFNA(VLOOKUP(LEFT('paste report'!K21,6),$AE$10:$AF$47,2,FALSE),"") -> 0.5 | Z21: =_xlfn.IFNA(VLOOKUP(RIGHT('paste report'!K21,6),$AE$10:$AF$47,2,FALSE),"") -> 0.83333333 | AA21: =IFERROR(24*IF(Z21>0,Z21-Y21,0),0) -> 8 | AE21: 10:30a | AF21: 0.4375
... B47: ='paste report'!A47 -> 01529 | C47: ='paste report'!B47 -> Natalie N. | D47: ='paste report'!C47 -> Nguyen | E47: =VLOOKUP(B47,Team!$B$4:$F$183,5,FALSE) -> CAS | F47: =I47+L47+O47+R47+U47+X47+AA47 -> 24 | G47: =_xlfn.IFNA(VLOOKUP(LEFT('paste report'!E47,6),$AE$10:$AF$47,2,FALSE),"") -> 0.45833333 | H47: =_xlfn.IFNA(VLOOKUP(RIGHT('paste report'!E47,6),$AE$10:$AF$47,2,FALSE),"") -> 0.79166667 | I47: =IFERROR(24*IF(H47>0,H47-G47,0),0) -> 8 | J47: =_xlfn.IFNA(VLOOKUP(LEFT('paste report'!F47,6),$AE$10:$AF$47,2,FALSE),"") | K47: =_xlfn.IFNA(VLOOKUP(RIGHT('paste report'!F47,6),$AE$10:$AF$47,2,FALSE),"") | L47: =IFERROR(24*IF(K47>0,K47-J47,0),0) -> 0 | M47: =_xlfn.IFNA(VLOOKUP(LEFT('paste report'!G47,6),$AE$10:$AF$47,2,FALSE),"") | N47: =_xlfn.IFNA(VLOOKUP(RIGHT('paste report'!G47,6),$AE$10:$AF$47,2,FALSE),"") | O47: =IFERROR(24*IF(N47>0,N47-M47,0),0) -> 0 | P47: =_xlfn.IFNA(VLOOKUP(LEFT('paste report'!H47,6),$AE$10:$AF$47,2,FALSE),"") | Q47: =_xlfn.IFNA(VLOOKUP(RIGHT('paste report'!H47,6),$AE$10:$AF$47,2,FALSE),"") | R47: =IFERROR(24*IF(Q47>0,Q47-P47,0),0) -> 0 | S47: =_xlfn.IFNA(VLOOKUP(LEFT('paste report'!I47,6),$AE$10:$AF$47,2,FALSE),"") -> 0.35416667 | T47: =_xlfn.IFNA(VLOOKUP(RIGHT('paste report'!I47,6),$AE$10:$AF$47,2,FALSE),"") -> 0.6875 | U47: =IFERROR(24*IF(T47>0,T47-S47,0),0) -> 8 | V47: =_xlfn.IFNA(VLOOKUP(LEFT('paste report'!J47,6),$AE$10:$AF$47,2,FALSE),"") -> 0.5 | W47: =_xlfn.IFNA(VLOOKUP(RIGHT('paste report'!J47,6),$AE$10:$AF$47,2,FALSE),"") -> 0.83333333 | X47: =IFERROR(24*IF(W47>0,W47-V47,0),0) -> 8 | Y47: =_xlfn.IFNA(VLOOKUP(LEFT('paste report'!K47,6),$AE$10:$AF$47,2,FALSE),"") | Z47: =_xlfn.IFNA(VLOOKUP(RIGHT('paste report'!K47,6),$AE$10:$AF$47,2,FALSE),"") | AA47: =IFERROR(24*IF(Z47>0,Z47-Y47,0),0) -> 0 | AE47: 11:30p | AF47: 0.97916667
B48: ='paste report'!A48 -> 1257 | C48: ='paste report'!B48 -> Noreen | D48: ='paste report'!C48 -> De Vera | E48: =VLOOKUP(B48,Team!$B$4:$F$183,5,FALSE) -> CAS | F48: =I48+L48+O48+R48+U48+X48+AA48 -> 0 | G48: =_xlfn.IFNA(VLOOKUP(LEFT('paste report'!E48,6),$AE$10:$AF$47,2,FALSE),"") | H48: =_xlfn.IFNA(VLOOKUP(RIGHT('paste report'!E48,6),$AE$10:$AF$47,2,FALSE),"") | I48: =IFERROR(24*IF(H48>0,H48-G48,0),0) -> 0 | J48: =_xlfn.IFNA(VLOOKUP(LEFT('paste report'!F48,6),$AE$10:$AF$47,2,FALSE),"") | K48: =_xlfn.IFNA(VLOOKUP(RIGHT('paste report'!F48,6),$AE$10:$AF$47,2,FALSE),"") | L48: =IFERROR(24*IF(K48>0,K48-J48,0),0) -> 0 | M48: =_xlfn.IFNA(VLOOKUP(LEFT('paste report'!G48,6),$AE$10:$AF$47,2,FALSE),"") | N48: =_xlfn.IFNA(VLOOKUP(RIGHT('paste report'!G48,6),$AE$10:$AF$47,2,FALSE),"") | O48: =IFERROR(24*IF(N48>0,N48-M48,0),0) -> 0 | P48: =_xlfn.IFNA(VLOOKUP(LEFT('paste report'!H48,6),$AE$10:$AF$47,2,FALSE),"") | Q48: =_xlfn.IFNA(VLOOKUP(RIGHT('paste report'!H48,6),$AE$10:$AF$47,2,FALSE),"") | R48: =IFERROR(24*IF(Q48>0,Q48-P48,0),0) -> 0 | S48: =_xlfn.IFNA(VLOOKUP(LEFT('paste report'!I48,6),$AE$10:$AF$47,2,FALSE),"") | T48: =_xlfn.IFNA(VLOOKUP(RIGHT('paste report'!I48,6),$AE$10:$AF$47,2,FALSE),"") | U48: =IFERROR(24*IF(T48>0,T48-S48,0),0) -> 0 | V48: =_xlfn.IFNA(VLOOKUP(LEFT('paste report'!J48,6),$AE$10:$AF$47,2,FALSE),"") | W48: =_xlfn.IFNA(VLOOKUP(RIGHT('paste report'!J48,6),$AE$10:$AF$47,2,FALSE),"") | X48: =IFERROR(24*IF(W48>0,W48-V48,0),0) -> 0 | Y48: =_xlfn.IFNA(VLOOKUP(LEFT('paste report'!K48,6),$AE$10:$AF$47,2,FALSE),"") | Z48: =_xlfn.IFNA(VLOOKUP(RIGHT('paste report'!K48,6),$AE$10:$AF$47,2,FALSE),"") | AA48: =IFERROR(24*IF(Z48>0,Z48-Y48,0),0) -> 0
B49: ='paste report'!A49 -> 1287 | C49: ='paste report'!B49 -> Pearl | D49: ='paste report'!C49 -> Lin | E49: =VLOOKUP(B49,Team!$B$4:$F$183,5,FALSE) -> PT | F49: =I49+L49+O49+R49+U49+X49+AA49 -> 0 | G49: =_xlfn.IFNA(VLOOKUP(LEFT('paste report'!E49,6),$AE$10:$AF$47,2,FALSE),"") | H49: =_xlfn.IFNA(VLOOKUP(RIGHT('paste report'!E49,6),$AE$10:$AF$47,2,FALSE),"") | I49: =IFERROR(24*IF(H49>0,H49-G49,0),0) -> 0 | J49: =_xlfn.IFNA(VLOOKUP(LEFT('paste report'!F49,6),$AE$10:$AF$47,2,FALSE),"") | K49: =_xlfn.IFNA(VLOOKUP(RIGHT('paste report'!F49,6),$AE$10:$AF$47,2,FALSE),"") | L49: =IFERROR(24*IF(K49>0,K49-J49,0),0) -> 0 | M49: =_xlfn.IFNA(VLOOKUP(LEFT('paste report'!G49,6),$AE$10:$AF$47,2,FALSE),"") | N49: =_xlfn.IFNA(VLOOKUP(RIGHT('paste report'!G49,6),$AE$10:$AF$47,2,FALSE),"") | O49: =IFERROR(24*IF(N49>0,N49-M49,0),0) -> 0 | P49: =_xlfn.IFNA(VLOOKUP(LEFT('paste report'!H49,6),$AE$10:$AF$47,2,FALSE),"") | Q49: =_xlfn.IFNA(VLOOKUP(RIGHT('paste report'!H49,6),$AE$10:$AF$47,2,FALSE),"") | R49: =IFERROR(24*IF(Q49>0,Q49-P49,0),0) -> 0 | S49: =_xlfn.IFNA(VLOOKUP(LEFT('paste report'!I49,6),$AE$10:$AF$47,2,FALSE),"") | T49: =_xlfn.IFNA(VLOOKUP(RIGHT('paste report'!I49,6),$AE$10:$AF$47,2,FALSE),"") | U49: =IFERROR(24*IF(T49>0,T49-S49,0),0) -> 0 | V49: =_xlfn.IFNA(VLOOKUP(LEFT('paste report'!J49,6),$AE$10:$AF$47,2,FALSE),"") | W49: =_xlfn.IFNA(VLOOKUP(RIGHT('paste report'!J49,6),$AE$10:$AF$47,2,FALSE),"") | X49: =IFERROR(24*IF(W49>0,W49-V49,0),0) -> 0 | Y49: =_xlfn.IFNA(VLOOKUP(LEFT('paste report'!K49,6),$AE$10:$AF$47,2,FALSE),"") | Z49: =_xlfn.IFNA(VLOOKUP(RIGHT('paste report'!K49,6),$AE$10:$AF$47,2,FALSE),"") | AA49: =IFERROR(24*IF(Z49>0,Z49-Y49,0),0) -> 0
B50: ='paste report'!A50 -> 1232 | C50: ='paste report'!B50 -> Penny | D50: ='paste report'!C50 -> Rabena | E50: =VLOOKUP(B50,Team!$B$4:$F$183,5,FALSE) -> CAS | F50: =I50+L50+O50+R50+U50+X50+AA50 -> 0 | G50: =_xlfn.IFNA(VLOOKUP(LEFT('paste report'!E50,6),$AE$10:$AF$47,2,FALSE),"") | H50: =_xlfn.IFNA(VLOOKUP(RIGHT('paste report'!E50,6),$AE$10:$AF$47,2,FALSE),"") | I50: =IFERROR(24*IF(H50>0,H50-G50,0),0) -> 0 | J50: =_xlfn.IFNA(VLOOKUP(LEFT('paste report'!F50,6),$AE$10:$AF$47,2,FALSE),"") | K50: =_xlfn.IFNA(VLOOKUP(RIGHT('paste report'!F50,6),$AE$10:$AF$47,2,FALSE),"") | L50: =IFERROR(24*IF(K50>0,K50-J50,0),0) -> 0 | M50: =_xlfn.IFNA(VLOOKUP(LEFT('paste report'!G50,6),$AE$10:$AF$47,2,FALSE),"") | N50: =_xlfn.IFNA(VLOOKUP(RIGHT('paste report'!G50,6),$AE$10:$AF$47,2,FALSE),"") | O50: =IFERROR(24*IF(N50>0,N50-M50,0),0) -> 0 | P50: =_xlfn.IFNA(VLOOKUP(LEFT('paste report'!H50,6),$AE$10:$AF$47,2,FALSE),"") | Q50: =_xlfn.IFNA(VLOOKUP(RIGHT('paste report'!H50,6),$AE$10:$AF$47,2,FALSE),"") | R50: =IFERROR(24*IF(Q50>0,Q50-P50,0),0) -> 0 | S50: =_xlfn.IFNA(VLOOKUP(LEFT('paste report'!I50,6),$AE$10:$AF$47,2,FALSE),"") | T50: =_xlfn.IFNA(VLOOKUP(RIGHT('paste report'!I50,6),$AE$10:$AF$47,2,FALSE),"") | U50: =IFERROR(24*IF(T50>0,T50-S50,0),0) -> 0 | V50: =_xlfn.IFNA(VLOOKUP(LEFT('paste report'!J50,6),$AE$10:$AF$47,2,FALSE),"") | W50: =_xlfn.IFNA(VLOOKUP(RIGHT('paste report'!J50,6),$AE$10:$AF$47,2,FALSE),"") | X50: =IFERROR(24*IF(W50>0,W50-V50,0),0) -> 0 | Y50: =_xlfn.IFNA(VLOOKUP(LEFT('paste report'!K50,6),$AE$10:$AF$47,2,FALSE),"") | Z50: =_xlfn.IFNA(VLOOKUP(RIGHT('paste report'!K50,6),$AE$10:$AF$47,2,FALSE),"") | AA50: =IFERROR(24*IF(Z50>0,Z50-Y50,0),0) -> 0
B51: ='paste report'!A51 -> 303 | C51: ='paste report'!B51 -> Rachel | D51: ='paste report'!C51 -> Seeto | E51: =VLOOKUP(B51,Team!$B$4:$F$183,5,FALSE) -> PT | F51: =I51+L51+O51+R51+U51+X51+AA51 -> 7 | G51: =_xlfn.IFNA(VLOOKUP(LEFT('paste report'!E51,6),$AE$10:$AF$47,2,FALSE),"") | H51: =_xlfn.IFNA(VLOOKUP(RIGHT('paste report'!E51,6),$AE$10:$AF$47,2,FALSE),"") | I51: =IFERROR(24*IF(H51>0,H51-G51,0),0) -> 0 | J51: =_xlfn.IFNA(VLOOKUP(LEFT('paste report'!F51,6),$AE$10:$AF$47,2,FALSE),"") | K51: =_xlfn.IFNA(VLOOKUP(RIGHT('paste report'!F51,6),$AE$10:$AF$47,2,FALSE),"") | L51: =IFERROR(24*IF(K51>0,K51-J51,0),0) -> 0 | M51: =_xlfn.IFNA(VLOOKUP(LEFT('paste report'!G51,6),$AE$10:$AF$47,2,FALSE),"") | N51: =_xlfn.IFNA(VLOOKUP(RIGHT('paste report'!G51,6),$AE$10:$AF$47,2,FALSE),"") | O51: =IFERROR(24*IF(N51>0,N51-M51,0),0) -> 0 | P51: =_xlfn.IFNA(VLOOKUP(LEFT('paste report'!H51,6),$AE$10:$AF$47,2,FALSE),"") | Q51: =_xlfn.IFNA(VLOOKUP(RIGHT('paste report'!H51,6),$AE$10:$AF$47,2,FALSE),"") | R51: =IFERROR(24*IF(Q51>0,Q51-P51,0),0) -> 0 | S51: =_xlfn.IFNA(VLOOKUP(LEFT('paste report'!I51,6),$AE$10:$AF$47,2,FALSE),"") -> 0.35416667 | T51: =_xlfn.IFNA(VLOOKUP(RIGHT('paste report'!I51,6),$AE$10:$AF$47,2,FALSE),"") -> 0.64583333 | U51: =IFERROR(24*IF(T51>0,T51-S51,0),0) -> 7 | V51: =_xlfn.IFNA(VLOOKUP(LEFT('paste report'!J51,6),$AE$10:$AF$47,2,FALSE),"") | W51: =_xlfn.IFNA(VLOOKUP(RIGHT('paste report'!J51,6),$AE$10:$AF$47,2,FALSE),"") | X51: =IFERROR(24*IF(W51>0,W51-V51,0),0) -> 0 | Y51: =_xlfn.IFNA(VLOOKUP(LEFT('paste report'!K51,6),$AE$10:$AF$47,2,FALSE),"") | Z51: =_xlfn.IFNA(VLOOKUP(RIGHT('paste report'!K51,6),$AE$10:$AF$47,2,FALSE),"") | AA51: =IFERROR(24*IF(Z51>0,Z51-Y51,0),0) -> 0
B52: ='paste report'!A52 -> 1142 | C52: ='paste report'!B52 -> Ralph | D52: ='paste report'!C52 -> Deoferio | E52: =VLOOKUP(B52,Team!$B$4:$F$183,5,FALSE) -> FT | F52: =I52+L52+O52+R52+U52+X52+AA52 -> 0 | G52: =_xlfn.IFNA(VLOOKUP(LEFT('paste report'!E52,6),$AE$10:$AF$47,2,FALSE),"") | H52: =_xlfn.IFNA(VLOOKUP(RIGHT('paste report'!E52,6),$AE$10:$AF$47,2,FALSE),"") | I52: =IFERROR(24*IF(H52>0,H52-G52,0),0) -> 0 | J52: =_xlfn.IFNA(VLOOKUP(LEFT('paste report'!F52,6),$AE$10:$AF$47,2,FALSE),"") | K52: =_xlfn.IFNA(VLOOKUP(RIGHT('paste report'!F52,6),$AE$10:$AF$47,2,FALSE),"") | L52: =IFERROR(24*IF(K52>0,K52-J52,0),0) -> 0 | M52: =_xlfn.IFNA(VLOOKUP(LEFT('paste report'!G52,6),$AE$10:$AF$47,2,FALSE),"") | N52: =_xlfn.IFNA(VLOOKUP(RIGHT('paste report'!G52,6),$AE$10:$AF$47,2,FALSE),"") | O52: =IFERROR(24*IF(N52>0,N52-M52,0),0) -> 0 | P52: =_xlfn.IFNA(VLOOKUP(LEFT('paste report'!H52,6),$AE$10:$AF$47,2,FALSE),"") | Q52: =_xlfn.IFNA(VLOOKUP(RIGHT('paste report'!H52,6),$AE$10:$AF$47,2,FALSE),"") | R52: =IFERROR(24*IF(Q52>0,Q52-P52,0),0) -> 0 | S52: =_xlfn.IFNA(VLOOKUP(LEFT('paste report'!I52,6),$AE$10:$AF$47,2,FALSE),"") | T52: =_xlfn.IFNA(VLOOKUP(RIGHT('paste report'!I52,6),$AE$10:$AF$47,2,FALSE),"") | U52: =IFERROR(24*IF(T52>0,T52-S52,0),0) -> 0 | V52: =_xlfn.IFNA(VLOOKUP(LEFT('paste report'!J52,6),$AE$10:$AF$47,2,FALSE),"") | W52: =_xlfn.IFNA(VLOOKUP(RIGHT('paste report'!J52,6),$AE$10:$AF$47,2,FALSE),"") | X52: =IFERROR(24*IF(W52>0,W52-V52,0),0) -> 0 | Y52: =_xlfn.IFNA(VLOOKUP(LEFT('paste report'!K52,6),$AE$10:$AF$47,2,FALSE),"") | Z52: =_xlfn.IFNA(VLOOKUP(RIGHT('paste report'!K52,6),$AE$10:$AF$47,2,FALSE),"") | AA52: =IFERROR(24*IF(Z52>0,Z52-Y52,0),0) -> 0
B53: ='paste report'!A53 -> 01528 | C53: ='paste report'!B53 -> Rena | D53: ='paste report'!C53 -> Chen | E53: =VLOOKUP(B53,Team!$B$4:$F$183,5,FALSE) -> CAS | F53: =I53+L53+O53+R53+U53+X53+AA53 -> 0 | G53: =_xlfn.IFNA(VLOOKUP(LEFT('paste report'!E53,6),$AE$10:$AF$47,2,FALSE),"") | H53: =_xlfn.IFNA(VLOOKUP(RIGHT('paste report'!E53,6),$AE$10:$AF$47,2,FALSE),"") | I53: =IFERROR(24*IF(H53>0,H53-G53,0),0) -> 0 | J53: =_xlfn.IFNA(VLOOKUP(LEFT('paste report'!F53,6),$AE$10:$AF$47,2,FALSE),"") | K53: =_xlfn.IFNA(VLOOKUP(RIGHT('paste report'!F53,6),$AE$10:$AF$47,2,FALSE),"") | L53: =IFERROR(24*IF(K53>0,K53-J53,0),0) -> 0 | M53: =_xlfn.IFNA(VLOOKUP(LEFT('paste report'!G53,6),$AE$10:$AF$47,2,FALSE),"") | N53: =_xlfn.IFNA(VLOOKUP(RIGHT('paste report'!G53,6),$AE$10:$AF$47,2,FALSE),"") | O53: =IFERROR(24*IF(N53>0,N53-M53,0),0) -> 0 | P53: =_xlfn.IFNA(VLOOKUP(LEFT('paste report'!H53,6),$AE$10:$AF$47,2,FALSE),"") | Q53: =_xlfn.IFNA(VLOOKUP(RIGHT('paste report'!H53,6),$AE$10:$AF$47,2,FALSE),"") | R53: =IFERROR(24*IF(Q53>0,Q53-P53,0),0) -> 0 | S53: =_xlfn.IFNA(VLOOKUP(LEFT('paste report'!I53,6),$AE$10:$AF$47,2,FALSE),"") | T53: =_xlfn.IFNA(VLOOKUP(RIGHT('paste report'!I53,6),$AE$10:$AF$47,2,FALSE),"") | U53: =IFERROR(24*IF(T53>0,T53-S53,0),0) -> 0 | V53: =_xlfn.IFNA(VLOOKUP(LEFT('paste report'!J53,6),$AE$10:$AF$47,2,FALSE),"") | W53: =_xlfn.IFNA(VLOOKUP(RIGHT('paste report'!J53,6),$AE$10:$AF$47,2,FALSE),"") | X53: =IFERROR(24*IF(W53>0,W53-V53,0),0) -> 0 | Y53: =_xlfn.IFNA(VLOOKUP(LEFT('paste report'!K53,6),$AE$10:$AF$47,2,FALSE),"") | Z53: =_xlfn.IFNA(VLOOKUP(RIGHT('paste report'!K53,6),$AE$10:$AF$47,2,FALSE),"") | AA53: =IFERROR(24*IF(Z53>0,Z53-Y53,0),0) -> 0
B54: ='paste report'!A54 -> 1237 | C54: ='paste report'!B54 -> Rich | D54: ='paste report'!C54 -> Ma | E54: =VLOOKUP(B54,Team!$B$4:$F$183,5,FALSE) -> PT | F54: =I54+L54+O54+R54+U54+X54+AA54 -> 24 | G54: =_xlfn.IFNA(VLOOKUP(LEFT('paste report'!E54,6),$AE$10:$AF$47,2,FALSE),"") | H54: =_xlfn.IFNA(VLOOKUP(RIGHT('paste report'!E54,6),$AE$10:$AF$47,2,FALSE),"") | I54: =IFERROR(24*IF(H54>0,H54-G54,0),0) -> 0 | J54: =_xlfn.IFNA(VLOOKUP(LEFT('paste report'!F54,6),$AE$10:$AF$47,2,FALSE),"") | K54: =_xlfn.IFNA(VLOOKUP(RIGHT('paste report'!F54,6),$AE$10:$AF$47,2,FALSE),"") | L54: =IFERROR(24*IF(K54>0,K54-J54,0),0) -> 0 | M54: =_xlfn.IFNA(VLOOKUP(LEFT('paste report'!G54,6),$AE$10:$AF$47,2,FALSE),"") | N54: =_xlfn.IFNA(VLOOKUP(RIGHT('paste report'!G54,6),$AE$10:$AF$47,2,FALSE),"") | O54: =IFERROR(24*IF(N54>0,N54-M54,0),0) -> 0 | P54: =_xlfn.IFNA(VLOOKUP(LEFT('paste report'!H54,6),$AE$10:$AF$47,2,FALSE),"") -> 0.45833333 | Q54: =_xlfn.IFNA(VLOOKUP(RIGHT('paste report'!H54,6),$AE$10:$AF$47,2,FALSE),"") -> 0.79166667 | R54: =IFERROR(24*IF(Q54>0,Q54-P54,0),0) -> 8 | S54: =_xlfn.IFNA(VLOOKUP(LEFT('paste report'!I54,6),$AE$10:$AF$47,2,FALSE),"") -> 0.35416667 | T54: =_xlfn.IFNA(VLOOKUP(RIGHT('paste report'!I54,6),$AE$10:$AF$47,2,FALSE),"") -> 0.6875 | U54: =IFERROR(24*IF(T54>0,T54-S54,0),0) -> 8 | V54: =_xlfn.IFNA(VLOOKUP(LEFT('paste report'!J54,6),$AE$10:$AF$47,2,FALSE),"") -> 0.375 | W54: =_xlfn.IFNA(VLOOKUP(RIGHT('paste report'!J54,6),$AE$10:$AF$47,2,FALSE),"") -> 0.70833333 | X54: =IFERROR(24*IF(W54>0,W54-V54,0),0) -> 8 | Y54: =_xlfn.IFNA(VLOOKUP(LEFT('paste report'!K54,6),$AE$10:$AF$47,2,FALSE),"") | Z54: =_xlfn.IFNA(VLOOKUP(RIGHT('paste report'!K54,6),$AE$10:$AF$47,2,FALSE),"") | AA54: =IFERROR(24*IF(Z54>0,Z54-Y54,0),0) -> 0
B55: ='paste report'!A55 -> 1133 | C55: ='paste report'!B55 -> Sarah | D55: ='paste report'!C55 -> Lee | E55: =VLOOKUP(B55,Team!$B$4:$F$183,5,FALSE) -> CAS | F55: =I55+L55+O55+R55+U55+X55+AA55 -> 0 | G55: =_xlfn.IFNA(VLOOKUP(LEFT('paste report'!E55,6),$AE$10:$AF$47,2,FALSE),"") | H55: =_xlfn.IFNA(VLOOKUP(RIGHT('paste report'!E55,6),$AE$10:$AF$47,2,FALSE),"") | I55: =IFERROR(24*IF(H55>0,H55-G55,0),0) -> 0 | J55: =_xlfn.IFNA(VLOOKUP(LEFT('paste report'!F55,6),$AE$10:$AF$47,2,FALSE),"") | K55: =_xlfn.IFNA(VLOOKUP(RIGHT('paste report'!F55,6),$AE$10:$AF$47,2,FALSE),"") | L55: =IFERROR(24*IF(K55>0,K55-J55,0),0) -> 0 | M55: =_xlfn.IFNA(VLOOKUP(LEFT('paste report'!G55,6),$AE$10:$AF$47,2,FALSE),"") | N55: =_xlfn.IFNA(VLOOKUP(RIGHT('paste report'!G55,6),$AE$10:$AF$47,2,FALSE),"") | O55: =IFERROR(24*IF(N55>0,N55-M55,0),0) -> 0 | P55: =_xlfn.IFNA(VLOOKUP(LEFT('paste report'!H55,6),$AE$10:$AF$47,2,FALSE),"") | Q55: =_xlfn.IFNA(VLOOKUP(RIGHT('paste report'!H55,6),$AE$10:$AF$47,2,FALSE),"") | R55: =IFERROR(24*IF(Q55>0,Q55-P55,0),0) -> 0 | S55: =_xlfn.IFNA(VLOOKUP(LEFT('paste report'!I55,6),$AE$10:$AF$47,2,FALSE),"") | T55: =_xlfn.IFNA(VLOOKUP(RIGHT('paste report'!I55,6),$AE$10:$AF$47,2,FALSE),"") | U55: =IFERROR(24*IF(T55>0,T55-S55,0),0) -> 0 | V55: =_xlfn.IFNA(VLOOKUP(LEFT('paste report'!J55,6),$AE$10:$AF$47,2,FALSE),"") | W55: =_xlfn.IFNA(VLOOKUP(RIGHT('paste report'!J55,6),$AE$10:$AF$47,2,FALSE),"") | X55: =IFERROR(24*IF(W55>0,W55-V55,0),0) -> 0 | Y55: =_xlfn.IFNA(VLOOKUP(LEFT('paste report'!K55,6),$AE$10:$AF$47,2,FALSE),"") | Z55: =_xlfn.IFNA(VLOOKUP(RIGHT('paste report'!K55,6),$AE$10:$AF$47,2,FALSE),"") | AA55: =IFERROR(24*IF(Z55>0,Z55-Y55,0),0) -> 0
B56: ='paste report'!A56 -> 891 | C56: ='paste report'!B56 -> Sienna | D56: ='paste report'!C56 -> Lim | E56: =VLOOKUP(B56,Team!$B$4:$F$183,5,FALSE) -> CAS | F56: =I56+L56+O56+R56+U56+X56+AA56 -> 40.5 | G56: =_xlfn.IFNA(VLOOKUP(LEFT('paste report'!E56,6),$AE$10:$AF$47,2,FALSE),"") -> 0.4375 | H56: =_xlfn.IFNA(VLOOKUP(RIGHT('paste report'!E56,6),$AE$10:$AF$47,2,FALSE),"") -> 0.79166667 | I56: =IFERROR(24*IF(H56>0,H56-G56,0),0) -> 8.5 | J56: =_xlfn.IFNA(VLOOKUP(LEFT('paste report'!F56,6),$AE$10:$AF$47,2,FALSE),"") -> 0.45833333 | K56: =_xlfn.IFNA(VLOOKUP(RIGHT('paste report'!F56,6),$AE$10:$AF$47,2,FALSE),"") -> 0.79166667 | L56: =IFERROR(24*IF(K56>0,K56-J56,0),0) -> 8 | M56: =_xlfn.IFNA(VLOOKUP(LEFT('paste report'!G56,6),$AE$10:$AF$47,2,FALSE),"") -> 0.45833333 | N56: =_xlfn.IFNA(VLOOKUP(RIGHT('paste report'!G56,6),$AE$10:$AF$47,2,FALSE),"") -> 0.79166667 | O56: =IFERROR(24*IF(N56>0,N56-M56,0),0) -> 8 | P56: =_xlfn.IFNA(VLOOKUP(LEFT('paste report'!H56,6),$AE$10:$AF$47,2,FALSE),"") -> 0.58333333 | Q56: =_xlfn.IFNA(VLOOKUP(RIGHT('paste report'!H56,6),$AE$10:$AF$47,2,FALSE),"") -> 0.91666667 | R56: =IFERROR(24*IF(Q56>0,Q56-P56,0),0) -> 8 | S56: =_xlfn.IFNA(VLOOKUP(LEFT('paste report'!I56,6),$AE$10:$AF$47,2,FALSE),"") | T56: =_xlfn.IFNA(VLOOKUP(RIGHT('paste report'!I56,6),$AE$10:$AF$47,2,FALSE),"") | U56: =IFERROR(24*IF(T56>0,T56-S56,0),0) -> 0 | V56: =_xlfn.IFNA(VLOOKUP(LEFT('paste report'!J56,6),$AE$10:$AF$47,2,FALSE),"") | W56: =_xlfn.IFNA(VLOOKUP(RIGHT('paste report'!J56,6),$AE$10:$AF$47,2,FALSE),"") | X56: =IFERROR(24*IF(W56>0,W56-V56,0),0) -> 0 | Y56: =_xlfn.IFNA(VLOOKUP(LEFT('paste report'!K56,6),$AE$10:$AF$47,2,FALSE),"") -> 0.375 | Z56: =_xlfn.IFNA(VLOOKUP(RIGHT('paste report'!K56,6),$AE$10:$AF$47,2,FALSE),"") -> 0.70833333 | AA56: =IFERROR(24*IF(Z56>0,Z56-Y56,0),0) -> 8
B57: ='paste report'!A57 -> 1108 | C57: ='paste report'!B57 -> Tara | D57: ='paste report'!C57 -> Turner | E57: =VLOOKUP(B57,Team!$B$4:$F$183,5,FALSE) -> FT | F57: =I57+L57+O57+R57+U57+X57+AA57 -> 40.5 | G57: =_xlfn.IFNA(VLOOKUP(LEFT('paste report'!E57,6),$AE$10:$AF$47,2,FALSE),"") | H57: =_xlfn.IFNA(VLOOKUP(RIGHT('paste report'!E57,6),$AE$10:$AF$47,2,FALSE),"") | I57: =IFERROR(24*IF(H57>0,H57-G57,0),0) -> 0 | J57: =_xlfn.IFNA(VLOOKUP(LEFT('paste report'!F57,6),$AE$10:$AF$47,2,FALSE),"") -> 0.35416667 | K57: =_xlfn.IFNA(VLOOKUP(RIGHT('paste report'!F57,6),$AE$10:$AF$47,2,FALSE),"") -> 0.70833333 | L57: =IFERROR(24*IF(K57>0,K57-J57,0),0) -> 8.5 | M57: =_xlfn.IFNA(VLOOKUP(LEFT('paste report'!G57,6),$AE$10:$AF$47,2,FALSE),"") -> 0.45833333 | N57: =_xlfn.IFNA(VLOOKUP(RIGHT('paste report'!G57,6),$AE$10:$AF$47,2,FALSE),"") -> 0.79166667 | O57: =IFERROR(24*IF(N57>0,N57-M57,0),0) -> 8 | P57: =_xlfn.IFNA(VLOOKUP(LEFT('paste report'!H57,6),$AE$10:$AF$47,2,FALSE),"") -> 0.5 | Q57: =_xlfn.IFNA(VLOOKUP(RIGHT('paste report'!H57,6),$AE$10:$AF$47,2,FALSE),"") -> 0.83333333 | R57: =IFERROR(24*IF(Q57>0,Q57-P57,0),0) -> 8 | S57: =_xlfn.IFNA(VLOOKUP(LEFT('paste report'!I57,6),$AE$10:$AF$47,2,FALSE),"") -> 0.45833333 | T57: =_xlfn.IFNA(VLOOKUP(RIGHT('paste report'!I57,6),$AE$10:$AF$47,2,FALSE),"") -> 0.79166667 | U57: =IFERROR(24*IF(T57>0,T57-S57,0),0) -> 8 | V57: =_xlfn.IFNA(VLOOKUP(LEFT('paste report'!J57,6),$AE$10:$AF$47,2,FALSE),"") -> 0.375 | W57: =_xlfn.IFNA(VLOOKUP(RIGHT('paste report'!J57,6),$AE$10:$AF$47,2,FALSE),"") -> 0.70833333 | X57: =IFERROR(24*IF(W57>0,W57-V57,0),0) -> 8 | Y57: =_xlfn.IFNA(VLOOKUP(LEFT('paste report'!K57,6),$AE$10:$AF$47,2,FALSE),"") | Z57: =_xlfn.IFNA(VLOOKUP(RIGHT('paste report'!K57,6),$AE$10:$AF$47,2,FALSE),"") | AA57: =IFERROR(24*IF(Z57>0,Z57-Y57,0),0) -> 0
B58: ='paste report'!A58 -> 01521 | C58: ='paste report'!B58 -> Tom | D58: ='paste report'!C58 -> Wu | E58: =VLOOKUP(B58,Team!$B$4:$F$183,5,FALSE) -> CAS | F58: =I58+L58+O58+R58+U58+X58+AA58 -> 0 | G58: =_xlfn.IFNA(VLOOKUP(LEFT('paste report'!E58,6),$AE$10:$AF$47,2,FALSE),"") | H58: =_xlfn.IFNA(VLOOKUP(RIGHT('paste report'!E58,6),$AE$10:$AF$47,2,FALSE),"") | I58: =IFERROR(24*IF(H58>0,H58-G58,0),0) -> 0 | J58: =_xlfn.IFNA(VLOOKUP(LEFT('paste report'!F58,6),$AE$10:$AF$47,2,FALSE),"") | K58: =_xlfn.IFNA(VLOOKUP(RIGHT('paste report'!F58,6),$AE$10:$AF$47,2,FALSE),"") | L58: =IFERROR(24*IF(K58>0,K58-J58,0),0) -> 0 | M58: =_xlfn.IFNA(VLOOKUP(LEFT('paste report'!G58,6),$AE$10:$AF$47,2,FALSE),"") | N58: =_xlfn.IFNA(VLOOKUP(RIGHT('paste report'!G58,6),$AE$10:$AF$47,2,FALSE),"") | O58: =IFERROR(24*IF(N58>0,N58-M58,0),0) -> 0 | P58: =_xlfn.IFNA(VLOOKUP(LEFT('paste report'!H58,6),$AE$10:$AF$47,2,FALSE),"") | Q58: =_xlfn.IFNA(VLOOKUP(RIGHT('paste report'!H58,6),$AE$10:$AF$47,2,FALSE),"") | R58: =IFERROR(24*IF(Q58>0,Q58-P58,0),0) -> 0 | S58: =_xlfn.IFNA(VLOOKUP(LEFT('paste report'!I58,6),$AE$10:$AF$47,2,FALSE),"") | T58: =_xlfn.IFNA(VLOOKUP(RIGHT('paste report'!I58,6),$AE$10:$AF$47,2,FALSE),"") | U58: =IFERROR(24*IF(T58>0,T58-S58,0),0) -> 0 | V58: =_xlfn.IFNA(VLOOKUP(LEFT('paste report'!J58,6),$AE$10:$AF$47,2,FALSE),"") | W58: =_xlfn.IFNA(VLOOKUP(RIGHT('paste report'!J58,6),$AE$10:$AF$47,2,FALSE),"") | X58: =IFERROR(24*IF(W58>0,W58-V58,0),0) -> 0 | Y58: =_xlfn.IFNA(VLOOKUP(LEFT('paste report'!K58,6),$AE$10:$AF$47,2,FALSE),"") | Z58: =_xlfn.IFNA(VLOOKUP(RIGHT('paste report'!K58,6),$AE$10:$AF$47,2,FALSE),"") | AA58: =IFERROR(24*IF(Z58>0,Z58-Y58,0),0) -> 0
B59: ='paste report'!A59 -> 1062 | C59: ='paste report'!B59 -> Tomoko | D59: ='paste report'!C59 -> Shimada | E59: =VLOOKUP(B59,Team!$B$4:$F$183,5,FALSE) -> CAS | F59: =I59+L59+O59+R59+U59+X59+AA59 -> 24 | G59: =_xlfn.IFNA(VLOOKUP(LEFT('paste report'!E59,6),$AE$10:$AF$47,2,FALSE),"") -> 0.35416667 | H59: =_xlfn.IFNA(VLOOKUP(RIGHT('paste report'!E59,6),$AE$10:$AF$47,2,FALSE),"") -> 0.6875 | I59: =IFERROR(24*IF(H59>0,H59-G59,0),0) -> 8 | J59: =_xlfn.IFNA(VLOOKUP(LEFT('paste report'!F59,6),$AE$10:$AF$47,2,FALSE),"") | K59: =_xlfn.IFNA(VLOOKUP(RIGHT('paste report'!F59,6),$AE$10:$AF$47,2,FALSE),"") | L59: =IFERROR(24*IF(K59>0,K59-J59,0),0) -> 0 | M59: =_xlfn.IFNA(VLOOKUP(LEFT('paste report'!G59,6),$AE$10:$AF$47,2,FALSE),"") | N59: =_xlfn.IFNA(VLOOKUP(RIGHT('paste report'!G59,6),$AE$10:$AF$47,2,FALSE),"") | O59: =IFERROR(24*IF(N59>0,N59-M59,0),0) -> 0 | P59: =_xlfn.IFNA(VLOOKUP(LEFT('paste report'!H59,6),$AE$10:$AF$47,2,FALSE),"") | Q59: =_xlfn.IFNA(VLOOKUP(RIGHT('paste report'!H59,6),$AE$10:$AF$47,2,FALSE),"") | R59: =IFERROR(24*IF(Q59>0,Q59-P59,0),0) -> 0 | S59: =_xlfn.IFNA(VLOOKUP(LEFT('paste report'!I59,6),$AE$10:$AF$47,2,FALSE),"") -> 0.35416667 | T59: =_xlfn.IFNA(VLOOKUP(RIGHT('paste report'!I59,6),$AE$10:$AF$47,2,FALSE),"") -> 0.6875 | U59: =IFERROR(24*IF(T59>0,T59-S59,0),0) -> 8 | V59: =_xlfn.IFNA(VLOOKUP(LEFT('paste report'!J59,6),$AE$10:$AF$47,2,FALSE),"") -> 0.5 | W59: =_xlfn.IFNA(VLOOKUP(RIGHT('paste report'!J59,6),$AE$10:$AF$47,2,FALSE),"") -> 0.83333333 | X59: =IFERROR(24*IF(W59>0,W59-V59,0),0) -> 8 | Y59: =_xlfn.IFNA(VLOOKUP(LEFT('paste report'!K59,6),$AE$10:$AF$47,2,FALSE),"") | Z59: =_xlfn.IFNA(VLOOKUP(RIGHT('paste report'!K59,6),$AE$10:$AF$47,2,FALSE),"") | AA59: =IFERROR(24*IF(Z59>0,Z59-Y59,0),0) -> 0
... B97: ='paste report'!A97 -> 0 | C97: ='paste report'!B97 -> 0 | D97: ='paste report'!C97 -> 0 | E97: =VLOOKUP(B97,Team!$B$4:$F$183,5,FALSE) -> #N/A | F97: =I97+L97+O97+R97+U97+X97+AA97 -> 0 | G97: =_xlfn.IFNA(VLOOKUP(LEFT('paste report'!E97,6),$AE$10:$AF$47,2,FALSE),"") | H97: =_xlfn.IFNA(VLOOKUP(RIGHT('paste report'!E97,6),$AE$10:$AF$47,2,FALSE),"") | I97: =IFERROR(24*IF(H97>0,H97-G97,0),0) -> 0 | J97: =_xlfn.IFNA(VLOOKUP(LEFT('paste report'!F97,6),$AE$10:$AF$47,2,FALSE),"") | K97: =_xlfn.IFNA(VLOOKUP(RIGHT('paste report'!F97,6),$AE$10:$AF$47,2,FALSE),"") | L97: =IFERROR(24*IF(K97>0,K97-J97,0),0) -> 0 | M97: =_xlfn.IFNA(VLOOKUP(LEFT('paste report'!G97,6),$AE$10:$AF$47,2,FALSE),"") | N97: =_xlfn.IFNA(VLOOKUP(RIGHT('paste report'!G97,6),$AE$10:$AF$47,2,FALSE),"") | O97: =IFERROR(24*IF(N97>0,N97-M97,0),0) -> 0 | P97: =_xlfn.IFNA(VLOOKUP(LEFT('paste report'!H97,6),$AE$10:$AF$47,2,FALSE),"") | Q97: =_xlfn.IFNA(VLOOKUP(RIGHT('paste report'!H97,6),$AE$10:$AF$47,2,FALSE),"") | R97: =IFERROR(24*IF(Q97>0,Q97-P97,0),0) -> 0 | S97: =_xlfn.IFNA(VLOOKUP(LEFT('paste report'!I97,6),$AE$10:$AF$47,2,FALSE),"") | T97: =_xlfn.IFNA(VLOOKUP(RIGHT('paste report'!I97,6),$AE$10:$AF$47,2,FALSE),"") | U97: =IFERROR(24*IF(T97>0,T97-S97,0),0) -> 0 | V97: =_xlfn.IFNA(VLOOKUP(LEFT('paste report'!J97,6),$AE$10:$AF$47,2,FALSE),"") | W97: =_xlfn.IFNA(VLOOKUP(RIGHT('paste report'!J97,6),$AE$10:$AF$47,2,FALSE),"") | X97: =IFERROR(24*IF(W97>0,W97-V97,0),0) -> 0 | Y97: =_xlfn.IFNA(VLOOKUP(LEFT('paste report'!K97,6),$AE$10:$AF$47,2,FALSE),"") | Z97: =_xlfn.IFNA(VLOOKUP(RIGHT('paste report'!K97,6),$AE$10:$AF$47,2,FALSE),"") | AA97: =IFERROR(24*IF(Z97>0,Z97-Y97,0),0) -> 0

Sheet Mon
T2: Garment | Y2: Household | AD2: Food | AE2: Break | AH2: Customer tasks | AL2: Team | AN2: Cleaning | AT2: Other
T3: M's | U3: L's | V3: K's | W3: M/K | X3: Acc. | Y3: Fab. | Z3: HW | AA3: Stat. | AB3: H&B | AC3: HH | AD3: F | AE3: 40 | AF3: 15 | AG3: 10 | AH3: R | AI3: FR | AJ3: LD | AK3: GR | AL3: H | AM3: MT | AN3: CL | AO3: Mirr. | AP3: Dust | AQ3: Vac. | AR3: CL S | AS3: Bin | AT3: DEL | AU3: RFID | AV3: Emb. | AW3: Tidy
C5: =Weekly!G2 -> Mon Nov 10 | H5: 7 | L5: 8 | P5: 9 | T5: 10 | X5: 11 | AB5: 12 | AF5: 13 | AJ5: 14 | AN5: 15 | AR5: 16 | AV5: 17 | AZ5: 18 | BD5: 19 | BH5: 20 | BL5: 21 | BP5: 22 | BT5: 0.95833333
H6: 00 | I6: 15 | J6: 30 | K6: 45 | L6: 00 | M6: 15 | N6: 30 | O6: 45 | P6: 00 | Q6: 15 | R6: 30 | S6: 45 | T6: 00 | U6: 15 | V6: 30 | W6: 45 | X6: 00 | Y6: 15 | Z6: 30 | AA6: 45 | AB6: 00 | AC6: 15 | AD6: 30 | AE6: 45 | AF6: 00 | AG6: 15 | AH6: 30 | AI6: 45 | AJ6: 00 | AK6: 15 | AL6: 30 | AM6: 45 | AN6: 00 | AO6: 15 | AP6: 30 | AQ6: 45 | AR6: 00 | AS6: 15 | AT6: 30 | AU6: 45 | AV6: 00 | AW6: 15 | AX6: 30 | AY6: 45 | AZ6: 00 | BA6: 15 | BB6: 30 | BC6: 45 | BD6: 00 | BE6: 15 | BF6: 30 | BG6: 45 | BH6: 00 | BI6: 15 | BJ6: 30 | BK6: 45 | BL6: 00 | BM6: 15 | BN6: 30 | BO6: 45 | BP6: 00 | BQ6: 15 | BR6: 30 | BS6: 45
G7: Register | H7: =COUNTIF(H17:H103,"R") -> 0 | I7: =COUNTIF(I17:I103,"R") -> 0 | J7: =COUNTIF(J17:J103,"R") -> 0 | K7: =COUNTIF(K17:K103,"R") -> 0 | L7: =COUNTIF(L17:L103,"R") -> 0 | M7: =COUNTIF(M17:M103,"R") -> 0 | N7: =COUNTIF(N17:N103,"R") -> 0 | O7: =COUNTIF(O17:O103,"R") -> 1 | ... BT7: =COUNTIF(BT17:BT103,"R") -> 0
G8: Fitting room | H8: =COUNTIF(H17:H103,"FR") -> 0 | I8: =COUNTIF(I17:I103,"FR") -> 0 | J8: =COUNTIF(J17:J103,"FR") -> 0 | K8: =COUNTIF(K17:K103,"FR") -> 0 | L8: =COUNTIF(L17:L103,"FR") -> 0 | M8: =COUNTIF(M17:M103,"FR") -> 0 | N8: =COUNTIF(N17:N103,"FR") -> 0 | O8: =COUNTIF(O17:O103,"FR") -> 0 | ... BT8: =COUNTIF(BT17:BT103,"FR") -> 0
G9: Lead | H9: =COUNTIF(H17:H103,"LD") -> 0 | I9: =COUNTIF(I17:I103,"LD") -> 0 | J9: =COUNTIF(J17:J103,"LD") -> 0 | K9: =COUNTIF(K17:K103,"LD") -> 0 | L9: =COUNTIF(L17:L103,"LD") -> 0 | M9: =COUNTIF(M17:M103,"LD") -> 0 | N9: =COUNTIF(N17:N103,"LD") -> 0 | O9: =COUNTIF(O17:O103,"LD") -> 0 | ... BT9: =COUNTIF(BT17:BT103,"LD") -> 0
G10: Greeter | H10: =COUNTIF(H17:H103,"GR") -> 0 | I10: =COUNTIF(I17:I103,"GR") -> 0 | J10: =COUNTIF(J17:J103,"GR") -> 0 | K10: =COUNTIF(K17:K103,"GR") -> 0 | L10: =COUNTIF(L17:L103,"GR") -> 0 | M10: =COUNTIF(M17:M103,"GR") -> 0 | N10: =COUNTIF(N17:N103,"GR") -> 0 | O10: =COUNTIF(O17:O103,"GR") -> 0 | ... BT10: =COUNTIF(BT17:BT103,"GR") -> 0
G11: Total | H11: =COUNTIF(H17:H103,"?*") -> 0 | I11: =COUNTIF(I17:I103,"?*") -> 0 | J11: =COUNTIF(J17:J103,"?*") -> 0 | K11: =COUNTIF(K17:K103,"?*") -> 0 | L11: =COUNTIF(L17:L103,"?*") -> 0 | M11: =COUNTIF(M17:M103,"?*") -> 0 | N11: =COUNTIF(N17:N103,"?*") -> 6 | O11: =COUNTIF(O17:O103,"?*") -> 6 | ... BT11: =COUNTIF(BT17:BT103,"?*") -> 0
